Workbook

Sheet Carga Web Cirugias
A1: Plantilla de carga web CRR - ingreso diario de pabellones | AM1: Plantilla de carga web CRR - ingreso diario de pabellones | AN1: Plantilla de carga web CRR - ingreso diario de pabellones | AO1: Plantilla de carga web CRR - ingreso diario de pabellones
A2: Obligatorio | B2: Obligatorio | C2: Obligatorio | D2: Obligatorio | E2: Obligatorio | F2: Obligatorio | G2: Opcional | H2: Obligatorio | I2: Opcional | J2: Automático | K2: Opcional | L2: Obligatorio | M2: Obligatorio | N2: Obligatorio | O2: Obligatorio primera cirugía | P2: Automático | Q2: Obligatorio si atraso primera hora | R2: Obligatorio si se realiza | S2: Obligatorio si se realiza | T2: Opcional | U2: Manual | V2: Manual | W2: Automático | X2: Automático | Y2: Automático | Z2: Automático | AA2: Obligatorio si recambio >15 min | AB2: Automático | AC2: Automático | AD2: Manual | AE2: Automático | AF2: Automático | AG2: Obligatorio si suspendido | AH2: Obligatorio si suspendido | AI2: Obligatorio si suspendido | AJ2: Opcional | AK2: Opcional | AL2: Opcional | AM2: Opcional | AN2: Opcional | AO2: Opcional | AP2: Automático | AQ2: Automático | AR2: Automático | AS2: Automático | AT2: Automático | AU2: Automático | AV2: Automático | AW2: Automático
A3: Fecha Quirofano | B3: Nombre | C3: Apellido | D3: Edad | E3: Descripción Intervención | F3: Especialidad | G3: Subespecialidad | H3: Codigo 1 | I3: Codigo 2 | J3: Categoria | K3: Anestesista | L3: Cirujano | M3: Quirofano | N3: Estado | O3: Ingreso Pabellon | P3: Clasificación ingreso 08:00-08:15 | Q3: Justificación Atraso Primera Hora | R3: Inicio Cirugia | S3: Termino Cirugia | T3: Salida Pabellon | U3: Inicio Funcionamiento Pabellon | V3: Termino Funcionamiento Pabellon | W3: Horario Funcionamiento Pabellon (Min) | X3: Ocupación Diaria Pabellón (%) | Y3: Tiempo recambio entre cirugías (Min) | Z3: Cumple recambio <=15 min | AA3: Justificación Recambio >15 Min | AB3: Demora Ingreso-Inicio Min | AC3: Duracion Cirugia Formula Min | AD3: Tiempo programado de cirugía en tabla (Min) | AE3: Diferencia Real - Programado Min | AF3: Asertividad | AG3: Causas Suspension | AH3: Motivo de Suspensión | AI3: Motivo Justificado | AJ3: Observaciones | AK3: Ingreso CMA ambulatorio | AL3: Hospitalizado posterior | AM3: Episodio | AN3: Diagnostico | AO3: Cirugia | AP3: Semana Inicio | AQ3: Semana Fin | AR3: Semana Lunes-Domingo | AS3: Mes Dashboard | AT3: Día Semana | AU3: ID Registro Dashboard | AV3: Validación Carga Dashboard | AW3: Detalle Suspensión Dashboard
J4: =IF(H4<>"",IFERROR(VLOOKUP(IFERROR(LEFT(H4,FIND("-",H4)-1),H4),'Catalogo MINSAL'!A:E,5,FALSE),""),IF(I4<>"",IFERROR(VLOOKUP(IFERROR(LEFT(I4,FIND("-",I4)-1),I4),'Catalogo MINSAL'!A:E,5,FALSE),""),"")) | P4: =IFERROR(IF(OR(O4="",A4="",M4=""),"",IF(SUMPRODUCT(($A$4:$A$500=A4)*($M$4:$M$500=M4)*($O$4:$O$500<>"")*(MOD($O$4:$O$500,1)<MOD(O4,1)))=0,IF(MOD(O4,1)<=TIME(8,15,0),"Ingreso adecuado primera hora","Atraso primera hora"),"No aplica")),"") | U4: =IFERROR(VLOOKUP(M4,'Horario Pabellones'!$A$4:$D$17,2,FALSE),"") | V4: =IFERROR(VLOOKUP(M4,'Horario Pabellones'!$A$4:$D$17,3,FALSE),"") | W4: =IFERROR(VLOOKUP(M4,'Horario Pabellones'!$A$4:$D$17,4,FALSE),"") | X4: =IFERROR(IF(OR(A4="",M4="",W4=""),"",(((_xludf.AGGREGATE(14,6,MOD($S$4:$S$500,1)/(($A$4:$A$500=A4)*($M$4:$M$500=M4)*($R$4:$R$500<>"")*($S$4:$S$500<>"")),1)-_xludf.AGGREGATE(15,6,MOD($R$4:$R$500,1)/(($A$4:$A$500=A4)*($M$4:$M$500=M4)*($R$4:$R$500<>"")*($S$4:$S$500<>"")),1))*1440)/60)/(W4/60)),"") | Y4: =IFERROR(IF(OR(O4="",A4="",M4=""),"",(IF(ISNUMBER(O4),MOD(O4,1),TIMEVALUE(O4))-LOOKUP(2,1/(($A$4:$A$500=A4)*($M$4:$M$500=M4)*($T$4:$T$500<>"")*($T$4:$T$500<IF(ISNUMBER(O4),MOD(O4,1),TIMEVALUE(O4)))),$T$4:$T$500))*1440),"") | Z4: =IFERROR(IF(Y4="","",IF(ROUND(Y4,0)<=15,"Cumple","No cumple")),"") | AB4: =IFERROR(IF(OR(O4="",R4=""),"",IF(IF(ISNUMBER(R4),MOD(R4,1),TIMEVALUE(R4))>=IF(ISNUMBER(O4),MOD(O4,1),TIMEVALUE(O4)),(IF(ISNUMBER(R4),MOD(R4,1),TIMEVALUE(R4))-IF(ISNUMBER(O4),MOD(O4,1),TIMEVALUE(O4)))*1440,(IF(ISNUMBER(R4),MOD(R4,1),TIMEVALUE(R4))+1-IF(ISNUMBER(O4),MOD(O4,1),TIMEVALUE(O4)))*1440)),"") | AC4: =IFERROR(IF(OR(R4="",S4=""),"",IF(IF(ISNUMBER(S4),MOD(S4,1),TIMEVALUE(S4))>=IF(ISNUMBER(R4),MOD(R4,1),TIMEVALUE(R4)),(IF(ISNUMBER(S4),MOD(S4,1),TIMEVALUE(S4))-IF(ISNUMBER(R4),MOD(R4,1),TIMEVALUE(R4)))*1440,(IF(ISNUMBER(S4),MOD(S4,1),TIMEVALUE(S4))+1-IF(ISNUMBER(R4),MOD(R4,1),TIMEVALUE(R4)))*1440)),"") | AE4: =IFERROR(IF(OR(AC4="",AD4=""),"",AC4-AD4),"") | AF4: =IFERROR(IF(AE4="","",IF(ROUND(AE4,0)>15,"Subestimacion",IF(ROUND(AE4,0)<-15,"Sobrestimacion","Asertivo"))),"") | AP4: =IF(A4="","",A4-WEEKDAY(A4,2)+1) | AQ4: =IF(AO4="","",AO4+6) | AR4: =IF(AO4="","","Semana "&TEXT(AO4,"dd-mm-yyyy")&" al "&TEXT(AP4,"dd-mm-yyyy")) | AS4: =IF(A4="","",TEXT(A4,"mmmm yyyy")) | AT4: =IF(A4="","",TEXT(A4,"dddd")) | AU4: =IF(A4="","","CRR-"&TEXT(A4,"yyyymmdd")&"-"&M4&"-"&TEXT(ROW()-3,"0000")) | AV4: =IF(A4="","",IF(OR(B4="",C4="",E4="",F4="",M4="",N4=""),"Revisar campos obligatorios",IF(AND(P4="Atraso primera hora",Q4=""),"Falta justificación atraso primera hora",IF(AND(Z4="No cumple",AA4=""),"Falta justificación recambio >15 min",IF(AND(ISNUMBER(SEARCH("suspend",N4)),OR(AG4="",AH4="")),"Falta causa/motivo suspensión","OK"))))) | AW4: =IF(N4="","",IF(ISNUMBER(SEARCH("suspend",N4)),IF(AND(AG4="",AH4=""),"Sin causa/motivo registrado",IF(AG4="",AH4,IF(AH4="",AG4,AG4&": "&AH4))),""))
J5: =IF(H5<>"",IFERROR(VLOOKUP(IFERROR(LEFT(H5,FIND("-",H5)-1),H5),'Catalogo MINSAL'!A:E,5,FALSE),""),IF(I5<>"",IFERROR(VLOOKUP(IFERROR(LEFT(I5,FIND("-",I5)-1),I5),'Catalogo MINSAL'!A:E,5,FALSE),""),"")) | P5: =IFERROR(IF(OR(O5="",A5="",M5=""),"",IF(SUMPRODUCT(($A$4:$A$500=A5)*($M$4:$M$500=M5)*($O$4:$O$500<>"")*(MOD($O$4:$O$500,1)<MOD(O5,1)))=0,IF(MOD(O5,1)<=TIME(8,15,0),"Ingreso adecuado primera hora","Atraso primera hora"),"No aplica")),"") | U5: =IFERROR(VLOOKUP(M5,'Horario Pabellones'!$A$4:$D$17,2,FALSE),"") | V5: =IFERROR(VLOOKUP(M5,'Horario Pabellones'!$A$4:$D$17,3,FALSE),"") | W5: =IFERROR(VLOOKUP(M5,'Horario Pabellones'!$A$4:$D$17,4,FALSE),"") | X5: =IFERROR(IF(OR(A5="",M5="",W5=""),"",(((_xludf.AGGREGATE(14,6,MOD($S$4:$S$500,1)/(($A$4:$A$500=A5)*($M$4:$M$500=M5)*($R$4:$R$500<>"")*($S$4:$S$500<>"")),1)-_xludf.AGGREGATE(15,6,MOD($R$4:$R$500,1)/(($A$4:$A$500=A5)*($M$4:$M$500=M5)*($R$4:$R$500<>"")*($S$4:$S$500<>"")),1))*1440)/60)/(W5/60)),"") | Y5: =IFERROR(IF(OR(O5="",A5="",M5=""),"",(IF(ISNUMBER(O5),MOD(O5,1),TIMEVALUE(O5))-LOOKUP(2,1/(($A$4:$A$500=A5)*($M$4:$M$500=M5)*($T$4:$T$500<>"")*($T$4:$T$500<IF(ISNUMBER(O5),MOD(O5,1),TIMEVALUE(O5)))),$T$4:$T$500))*1440),"") | Z5: =IFERROR(IF(Y5="","",IF(ROUND(Y5,0)<=15,"Cumple","No cumple")),"") | AB5: =IFERROR(IF(OR(O5="",R5=""),"",IF(IF(ISNUMBER(R5),MOD(R5,1),TIMEVALUE(R5))>=IF(ISNUMBER(O5),MOD(O5,1),TIMEVALUE(O5)),(IF(ISNUMBER(R5),MOD(R5,1),TIMEVALUE(R5))-IF(ISNUMBER(O5),MOD(O5,1),TIMEVALUE(O5)))*1440,(IF(ISNUMBER(R5),MOD(R5,1),TIMEVALUE(R5))+1-IF(ISNUMBER(O5),MOD(O5,1),TIMEVALUE(O5)))*1440)),"") | AC5: =IFERROR(IF(OR(R5="",S5=""),"",IF(IF(ISNUMBER(S5),MOD(S5,1),TIMEVALUE(S5))>=IF(ISNUMBER(R5),MOD(R5,1),TIMEVALUE(R5)),(IF(ISNUMBER(S5),MOD(S5,1),TIMEVALUE(S5))-IF(ISNUMBER(R5),MOD(R5,1),TIMEVALUE(R5)))*1440,(IF(ISNUMBER(S5),MOD(S5,1),TIMEVALUE(S5))+1-IF(ISNUMBER(R5),MOD(R5,1),TIMEVALUE(R5)))*1440)),"") | AE5: =IFERROR(IF(OR(AC5="",AD5=""),"",AC5-AD5),"") | AF5: =IFERROR(IF(AE5="","",IF(ROUND(AE5,0)>15,"Subestimacion",IF(ROUND(AE5,0)<-15,"Sobrestimacion","Asertivo"))),"") | AP5: =IF(A5="","",A5-WEEKDAY(A5,2)+1) | AQ5: =IF(AO5="","",AO5+6) | AR5: =IF(AO5="","","Semana "&TEXT(AO5,"dd-mm-yyyy")&" al "&TEXT(AP5,"dd-mm-yyyy")) | AS5: =IF(A5="","",TEXT(A5,"mmmm yyyy")) | AT5: =IF(A5="","",TEXT(A5,"dddd")) | AU5: =IF(A5="","","CRR-"&TEXT(A5,"yyyymmdd")&"-"&M5&"-"&TEXT(ROW()-3,"0000")) | AV5: =IF(A5="","",IF(OR(B5="",C5="",E5="",F5="",M5="",N5=""),"Revisar campos obligatorios",IF(AND(P5="Atraso primera hora",Q5=""),"Falta justificación atraso primera hora",IF(AND(Z5="No cumple",AA5=""),"Falta justificación recambio >15 min",IF(AND(ISNUMBER(SEARCH("suspend",N5)),OR(AG5="",AH5="")),"Falta causa/motivo suspensión","OK"))))) | AW5: =IF(N5="","",IF(ISNUMBER(SEARCH("suspend",N5)),IF(AND(AG5="",AH5=""),"Sin causa/motivo registrado",IF(AG5="",AH5,IF(AH5="",AG5,AG5&": "&AH5))),""))
J6: =IF(H6<>"",IFERROR(VLOOKUP(IFERROR(LEFT(H6,FIND("-",H6)-1),H6),'Catalogo MINSAL'!A:E,5,FALSE),""),IF(I6<>"",IFERROR(VLOOKUP(IFERROR(LEFT(I6,FIND("-",I6)-1),I6),'Catalogo MINSAL'!A:E,5,FALSE),""),"")) | P6: =IFERROR(IF(OR(O6="",A6="",M6=""),"",IF(SUMPRODUCT(($A$4:$A$500=A6)*($M$4:$M$500=M6)*($O$4:$O$500<>"")*(MOD($O$4:$O$500,1)<MOD(O6,1)))=0,IF(MOD(O6,1)<=TIME(8,15,0),"Ingreso adecuado primera hora","Atraso primera hora"),"No aplica")),"") | U6: =IFERROR(VLOOKUP(M6,'Horario Pabellones'!$A$4:$D$17,2,FALSE),"") | V6: =IFERROR(VLOOKUP(M6,'Horario Pabellones'!$A$4:$D$17,3,FALSE),"") | W6: =IFERROR(VLOOKUP(M6,'Horario Pabellones'!$A$4:$D$17,4,FALSE),"") | X6: =IFERROR(IF(OR(A6="",M6="",W6=""),"",(((_xludf.AGGREGATE(14,6,MOD($S$4:$S$500,1)/(($A$4:$A$500=A6)*($M$4:$M$500=M6)*($R$4:$R$500<>"")*($S$4:$S$500<>"")),1)-_xludf.AGGREGATE(15,6,MOD($R$4:$R$500,1)/(($A$4:$A$500=A6)*($M$4:$M$500=M6)*($R$4:$R$500<>"")*($S$4:$S$500<>"")),1))*1440)/60)/(W6/60)),"") | Y6: =IFERROR(IF(OR(O6="",A6="",M6=""),"",(IF(ISNUMBER(O6),MOD(O6,1),TIMEVALUE(O6))-LOOKUP(2,1/(($A$4:$A$500=A6)*($M$4:$M$500=M6)*($T$4:$T$500<>"")*($T$4:$T$500<IF(ISNUMBER(O6),MOD(O6,1),TIMEVALUE(O6)))),$T$4:$T$500))*1440),"") | Z6: =IFERROR(IF(Y6="","",IF(ROUND(Y6,0)<=15,"Cumple","No cumple")),"") | AB6: =IFERROR(IF(OR(O6="",R6=""),"",IF(IF(ISNUMBER(R6),MOD(R6,1),TIMEVALUE(R6))>=IF(ISNUMBER(O6),MOD(O6,1),TIMEVALUE(O6)),(IF(ISNUMBER(R6),MOD(R6,1),TIMEVALUE(R6))-IF(ISNUMBER(O6),MOD(O6,1),TIMEVALUE(O6)))*1440,(IF(ISNUMBER(R6),MOD(R6,1),TIMEVALUE(R6))+1-IF(ISNUMBER(O6),MOD(O6,1),TIMEVALUE(O6)))*1440)),"") | AC6: =IFERROR(IF(OR(R6="",S6=""),"",IF(IF(ISNUMBER(S6),MOD(S6,1),TIMEVALUE(S6))>=IF(ISNUMBER(R6),MOD(R6,1),TIMEVALUE(R6)),(IF(ISNUMBER(S6),MOD(S6,1),TIMEVALUE(S6))-IF(ISNUMBER(R6),MOD(R6,1),TIMEVALUE(R6)))*1440,(IF(ISNUMBER(S6),MOD(S6,1),TIMEVALUE(S6))+1-IF(ISNUMBER(R6),MOD(R6,1),TIMEVALUE(R6)))*1440)),"") | AE6: =IFERROR(IF(OR(AC6="",AD6=""),"",AC6-AD6),"") | AF6: =IFERROR(IF(AE6="","",IF(ROUND(AE6,0)>15,"Subestimacion",IF(ROUND(AE6,0)<-15,"Sobrestimacion","Asertivo"))),"") | AP6: =IF(A6="","",A6-WEEKDAY(A6,2)+1) | AQ6: =IF(AO6="","",AO6+6) | AR6: =IF(AO6="","","Semana "&TEXT(AO6,"dd-mm-yyyy")&" al "&TEXT(AP6,"dd-mm-yyyy")) | AS6: =IF(A6="","",TEXT(A6,"mmmm yyyy")) | AT6: =IF(A6="","",TEXT(A6,"dddd")) | AU6: =IF(A6="","","CRR-"&TEXT(A6,"yyyymmdd")&"-"&M6&"-"&TEXT(ROW()-3,"0000")) | AV6: =IF(A6="","",IF(OR(B6="",C6="",E6="",F6="",M6="",N6=""),"Revisar campos obligatorios",IF(AND(P6="Atraso primera hora",Q6=""),"Falta justificación atraso primera hora",IF(AND(Z6="No cumple",AA6=""),"Falta justificación recambio >15 min",IF(AND(ISNUMBER(SEARCH("suspend",N6)),OR(AG6="",AH6="")),"Falta causa/motivo suspensión","OK"))))) | AW6: =IF(N6="","",IF(ISNUMBER(SEARCH("suspend",N6)),IF(AND(AG6="",AH6=""),"Sin causa/motivo registrado",IF(AG6="",AH6,IF(AH6="",AG6,AG6&": "&AH6))),""))
J7: =IF(H7<>"",IFERROR(VLOOKUP(IFERROR(LEFT(H7,FIND("-",H7)-1),H7),'Catalogo MINSAL'!A:E,5,FALSE),""),IF(I7<>"",IFERROR(VLOOKUP(IFERROR(LEFT(I7,FIND("-",I7)-1),I7),'Catalogo MINSAL'!A:E,5,FALSE),""),"")) | P7: =IFERROR(IF(OR(O7="",A7="",M7=""),"",IF(SUMPRODUCT(($A$4:$A$500=A7)*($M$4:$M$500=M7)*($O$4:$O$500<>"")*(MOD($O$4:$O$500,1)<MOD(O7,1)))=0,IF(MOD(O7,1)<=TIME(8,15,0),"Ingreso adecuado primera hora","Atraso primera hora"),"No aplica")),"") | U7: =IFERROR(VLOOKUP(M7,'Horario Pabellones'!$A$4:$D$17,2,FALSE),"") | V7: =IFERROR(VLOOKUP(M7,'Horario Pabellones'!$A$4:$D$17,3,FALSE),"") | W7: =IFERROR(VLOOKUP(M7,'Horario Pabellones'!$A$4:$D$17,4,FALSE),"") | X7: =IFERROR(IF(OR(A7="",M7="",W7=""),"",(((_xludf.AGGREGATE(14,6,MOD($S$4:$S$500,1)/(($A$4:$A$500=A7)*($M$4:$M$500=M7)*($R$4:$R$500<>"")*($S$4:$S$500<>"")),1)-_xludf.AGGREGATE(15,6,MOD($R$4:$R$500,1)/(($A$4:$A$500=A7)*($M$4:$M$500=M7)*($R$4:$R$500<>"")*($S$4:$S$500<>"")),1))*1440)/60)/(W7/60)),"") | Y7: =IFERROR(IF(OR(O7="",A7="",M7=""),"",(IF(ISNUMBER(O7),MOD(O7,1),TIMEVALUE(O7))-LOOKUP(2,1/(($A$4:$A$500=A7)*($M$4:$M$500=M7)*($T$4:$T$500<>"")*($T$4:$T$500<IF(ISNUMBER(O7),MOD(O7,1),TIMEVALUE(O7)))),$T$4:$T$500))*1440),"") | Z7: =IFERROR(IF(Y7="","",IF(ROUND(Y7,0)<=15,"Cumple","No cumple")),"") | AB7: =IFERROR(IF(OR(O7="",R7=""),"",IF(IF(ISNUMBER(R7),MOD(R7,1),TIMEVALUE(R7))>=IF(ISNUMBER(O7),MOD(O7,1),TIMEVALUE(O7)),(IF(ISNUMBER(R7),MOD(R7,1),TIMEVALUE(R7))-IF(ISNUMBER(O7),MOD(O7,1),TIMEVALUE(O7)))*1440,(IF(ISNUMBER(R7),MOD(R7,1),TIMEVALUE(R7))+1-IF(ISNUMBER(O7),MOD(O7,1),TIMEVALUE(O7)))*1440)),"") | AC7: =IFERROR(IF(OR(R7="",S7=""),"",IF(IF(ISNUMBER(S7),MOD(S7,1),TIMEVALUE(S7))>=IF(ISNUMBER(R7),MOD(R7,1),TIMEVALUE(R7)),(IF(ISNUMBER(S7),MOD(S7,1),TIMEVALUE(S7))-IF(ISNUMBER(R7),MOD(R7,1),TIMEVALUE(R7)))*1440,(IF(ISNUMBER(S7),MOD(S7,1),TIMEVALUE(S7))+1-IF(ISNUMBER(R7),MOD(R7,1),TIMEVALUE(R7)))*1440)),"") | AE7: =IFERROR(IF(OR(AC7="",AD7=""),"",AC7-AD7),"") | AF7: =IFERROR(IF(AE7="","",IF(ROUND(AE7,0)>15,"Subestimacion",IF(ROUND(AE7,0)<-15,"Sobrestimacion","Asertivo"))),"") | AP7: =IF(A7="","",A7-WEEKDAY(A7,2)+1) | AQ7: =IF(AO7="","",AO7+6) | AR7: =IF(AO7="","","Semana "&TEXT(AO7,"dd-mm-yyyy")&" al "&TEXT(AP7,"dd-mm-yyyy")) | AS7: =IF(A7="","",TEXT(A7,"mmmm yyyy")) | AT7: =IF(A7="","",TEXT(A7,"dddd")) | AU7: =IF(A7="","","CRR-"&TEXT(A7,"yyyymmdd")&"-"&M7&"-"&TEXT(ROW()-3,"0000")) | AV7: =IF(A7="","",IF(OR(B7="",C7="",E7="",F7="",M7="",N7=""),"Revisar campos obligatorios",IF(AND(P7="Atraso primera hora",Q7=""),"Falta justificación atraso primera hora",IF(AND(Z7="No cumple",AA7=""),"Falta justificación recambio >15 min",IF(AND(ISNUMBER(SEARCH("suspend",N7)),OR(AG7="",AH7="")),"Falta causa/motivo suspensión","OK"))))) | AW7: =IF(N7="","",IF(ISNUMBER(SEARCH("suspend",N7)),IF(AND(AG7="",AH7=""),"Sin causa/motivo registrado",IF(AG7="",AH7,IF(AH7="",AG7,AG7&": "&AH7))),""))
J8: =IF(H8<>"",IFERROR(VLOOKUP(IFERROR(LEFT(H8,FIND("-",H8)-1),H8),'Catalogo MINSAL'!A:E,5,FALSE),""),IF(I8<>"",IFERROR(VLOOKUP(IFERROR(LEFT(I8,FIND("-",I8)-1),I8),'Catalogo MINSAL'!A:E,5,FALSE),""),"")) | P8: =IFERROR(IF(OR(O8="",A8="",M8=""),"",IF(SUMPRODUCT(($A$4:$A$500=A8)*($M$4:$M$500=M8)*($O$4:$O$500<>"")*(MOD($O$4:$O$500,1)<MOD(O8,1)))=0,IF(MOD(O8,1)<=TIME(8,15,0),"Ingreso adecuado primera hora","Atraso primera hora"),"No aplica")),"") | U8: =IFERROR(VLOOKUP(M8,'Horario Pabellones'!$A$4:$D$17,2,FALSE),"") | V8: =IFERROR(VLOOKUP(M8,'Horario Pabellones'!$A$4:$D$17,3,FALSE),"") | W8: =IFERROR(VLOOKUP(M8,'Horario Pabellones'!$A$4:$D$17,4,FALSE),"") | X8: =IFERROR(IF(OR(A8="",M8="",W8=""),"",(((_xludf.AGGREGATE(14,6,MOD($S$4:$S$500,1)/(($A$4:$A$500=A8)*($M$4:$M$500=M8)*($R$4:$R$500<>"")*($S$4:$S$500<>"")),1)-_xludf.AGGREGATE(15,6,MOD($R$4:$R$500,1)/(($A$4:$A$500=A8)*($M$4:$M$500=M8)*($R$4:$R$500<>"")*($S$4:$S$500<>"")),1))*1440)/60)/(W8/60)),"") | Y8: =IFERROR(IF(OR(O8="",A8="",M8=""),"",(IF(ISNUMBER(O8),MOD(O8,1),TIMEVALUE(O8))-LOOKUP(2,1/(($A$4:$A$500=A8)*($M$4:$M$500=M8)*($T$4:$T$500<>"")*($T$4:$T$500<IF(ISNUMBER(O8),MOD(O8,1),TIMEVALUE(O8)))),$T$4:$T$500))*1440),"") | Z8: =IFERROR(IF(Y8="","",IF(ROUND(Y8,0)<=15,"Cumple","No cumple")),"") | AB8: =IFERROR(IF(OR(O8="",R8=""),"",IF(IF(ISNUMBER(R8),MOD(R8,1),TIMEVALUE(R8))>=IF(ISNUMBER(O8),MOD(O8,1),TIMEVALUE(O8)),(IF(ISNUMBER(R8),MOD(R8,1),TIMEVALUE(R8))-IF(ISNUMBER(O8),MOD(O8,1),TIMEVALUE(O8)))*1440,(IF(ISNUMBER(R8),MOD(R8,1),TIMEVALUE(R8))+1-IF(ISNUMBER(O8),MOD(O8,1),TIMEVALUE(O8)))*1440)),"") | AC8: =IFERROR(IF(OR(R8="",S8=""),"",IF(IF(ISNUMBER(S8),MOD(S8,1),TIMEVALUE(S8))>=IF(ISNUMBER(R8),MOD(R8,1),TIMEVALUE(R8)),(IF(ISNUMBER(S8),MOD(S8,1),TIMEVALUE(S8))-IF(ISNUMBER(R8),MOD(R8,1),TIMEVALUE(R8)))*1440,(IF(ISNUMBER(S8),MOD(S8,1),TIMEVALUE(S8))+1-IF(ISNUMBER(R8),MOD(R8,1),TIMEVALUE(R8)))*1440)),"") | AE8: =IFERROR(IF(OR(AC8="",AD8=""),"",AC8-AD8),"") | AF8: =IFERROR(IF(AE8="","",IF(ROUND(AE8,0)>15,"Subestimacion",IF(ROUND(AE8,0)<-15,"Sobrestimacion","Asertivo"))),"") | AP8: =IF(A8="","",A8-WEEKDAY(A8,2)+1) | AQ8: =IF(AO8="","",AO8+6) | AR8: =IF(AO8="","","Semana "&TEXT(AO8,"dd-mm-yyyy")&" al "&TEXT(AP8,"dd-mm-yyyy")) | AS8: =IF(A8="","",TEXT(A8,"mmmm yyyy")) | AT8: =IF(A8="","",TEXT(A8,"dddd")) | AU8: =IF(A8="","","CRR-"&TEXT(A8,"yyyymmdd")&"-"&M8&"-"&TEXT(ROW()-3,"0000")) | AV8: =IF(A8="","",IF(OR(B8="",C8="",E8="",F8="",M8="",N8=""),"Revisar campos obligatorios",IF(AND(P8="Atraso primera hora",Q8=""),"Falta justificación atraso primera hora",IF(AND(Z8="No cumple",AA8=""),"Falta justificación recambio >15 min",IF(AND(ISNUMBER(SEARCH("suspend",N8)),OR(AG8="",AH8="")),"Falta causa/motivo suspensión","OK"))))) | AW8: =IF(N8="","",IF(ISNUMBER(SEARCH("suspend",N8)),IF(AND(AG8="",AH8=""),"Sin causa/motivo registrado",IF(AG8="",AH8,IF(AH8="",AG8,AG8&": "&AH8))),""))
J9: =IF(H9<>"",IFERROR(VLOOKUP(IFERROR(LEFT(H9,FIND("-",H9)-1),H9),'Catalogo MINSAL'!A:E,5,FALSE),""),IF(I9<>"",IFERROR(VLOOKUP(IFERROR(LEFT(I9,FIND("-",I9)-1),I9),'Catalogo MINSAL'!A:E,5,FALSE),""),"")) | P9: =IFERROR(IF(OR(O9="",A9="",M9=""),"",IF(SUMPRODUCT(($A$4:$A$500=A9)*($M$4:$M$500=M9)*($O$4:$O$500<>"")*(MOD($O$4:$O$500,1)<MOD(O9,1)))=0,IF(MOD(O9,1)<=TIME(8,15,0),"Ingreso adecuado primera hora","Atraso primera hora"),"No aplica")),"") | U9: =IFERROR(VLOOKUP(M9,'Horario Pabellones'!$A$4:$D$17,2,FALSE),"") | V9: =IFERROR(VLOOKUP(M9,'Horario Pabellones'!$A$4:$D$17,3,FALSE),"") | W9: =IFERROR(VLOOKUP(M9,'Horario Pabellones'!$A$4:$D$17,4,FALSE),"") | X9: =IFERROR(IF(OR(A9="",M9="",W9=""),"",(((_xludf.AGGREGATE(14,6,MOD($S$4:$S$500,1)/(($A$4:$A$500=A9)*($M$4:$M$500=M9)*($R$4:$R$500<>"")*($S$4:$S$500<>"")),1)-_xludf.AGGREGATE(15,6,MOD($R$4:$R$500,1)/(($A$4:$A$500=A9)*($M$4:$M$500=M9)*($R$4:$R$500<>"")*($S$4:$S$500<>"")),1))*1440)/60)/(W9/60)),"") | Y9: =IFERROR(IF(OR(O9="",A9="",M9=""),"",(IF(ISNUMBER(O9),MOD(O9,1),TIMEVALUE(O9))-LOOKUP(2,1/(($A$4:$A$500=A9)*($M$4:$M$500=M9)*($T$4:$T$500<>"")*($T$4:$T$500<IF(ISNUMBER(O9),MOD(O9,1),TIMEVALUE(O9)))),$T$4:$T$500))*1440),"") | Z9: =IFERROR(IF(Y9="","",IF(ROUND(Y9,0)<=15,"Cumple","No cumple")),"") | AB9: =IFERROR(IF(OR(O9="",R9=""),"",IF(IF(ISNUMBER(R9),MOD(R9,1),TIMEVALUE(R9))>=IF(ISNUMBER(O9),MOD(O9,1),TIMEVALUE(O9)),(IF(ISNUMBER(R9),MOD(R9,1),TIMEVALUE(R9))-IF(ISNUMBER(O9),MOD(O9,1),TIMEVALUE(O9)))*1440,(IF(ISNUMBER(R9),MOD(R9,1),TIMEVALUE(R9))+1-IF(ISNUMBER(O9),MOD(O9,1),TIMEVALUE(O9)))*1440)),"") | AC9: =IFERROR(IF(OR(R9="",S9=""),"",IF(IF(ISNUMBER(S9),MOD(S9,1),TIMEVALUE(S9))>=IF(ISNUMBER(R9),MOD(R9,1),TIMEVALUE(R9)),(IF(ISNUMBER(S9),MOD(S9,1),TIMEVALUE(S9))-IF(ISNUMBER(R9),MOD(R9,1),TIMEVALUE(R9)))*1440,(IF(ISNUMBER(S9),MOD(S9,1),TIMEVALUE(S9))+1-IF(ISNUMBER(R9),MOD(R9,1),TIMEVALUE(R9)))*1440)),"") | AE9: =IFERROR(IF(OR(AC9="",AD9=""),"",AC9-AD9),"") | AF9: =IFERROR(IF(AE9="","",IF(ROUND(AE9,0)>15,"Subestimacion",IF(ROUND(AE9,0)<-15,"Sobrestimacion","Asertivo"))),"") | AP9: =IF(A9="","",A9-WEEKDAY(A9,2)+1) | AQ9: =IF(AO9="","",AO9+6) | AR9: =IF(AO9="","","Semana "&TEXT(AO9,"dd-mm-yyyy")&" al "&TEXT(AP9,"dd-mm-yyyy")) | AS9: =IF(A9="","",TEXT(A9,"mmmm yyyy")) | AT9: =IF(A9="","",TEXT(A9,"dddd")) | AU9: =IF(A9="","","CRR-"&TEXT(A9,"yyyymmdd")&"-"&M9&"-"&TEXT(ROW()-3,"0000")) | AV9: =IF(A9="","",IF(OR(B9="",C9="",E9="",F9="",M9="",N9=""),"Revisar campos obligatorios",IF(AND(P9="Atraso primera hora",Q9=""),"Falta justificación atraso primera hora",IF(AND(Z9="No cumple",AA9=""),"Falta justificación recambio >15 min",IF(AND(ISNUMBER(SEARCH("suspend",N9)),OR(AG9="",AH9="")),"Falta causa/motivo suspensión","OK"))))) | AW9: =IF(N9="","",IF(ISNUMBER(SEARCH("suspend",N9)),IF(AND(AG9="",AH9=""),"Sin causa/motivo registrado",IF(AG9="",AH9,IF(AH9="",AG9,AG9&": "&AH9))),""))
J10: =IF(H10<>"",IFERROR(VLOOKUP(IFERROR(LEFT(H10,FIND("-",H10)-1),H10),'Catalogo MINSAL'!A:E,5,FALSE),""),IF(I10<>"",IFERROR(VLOOKUP(IFERROR(LEFT(I10,FIND("-",I10)-1),I10),'Catalogo MINSAL'!A:E,5,FALSE),""),"")) | P10: =IFERROR(IF(OR(O10="",A10="",M10=""),"",IF(SUMPRODUCT(($A$4:$A$500=A10)*($M$4:$M$500=M10)*($O$4:$O$500<>"")*(MOD($O$4:$O$500,1)<MOD(O10,1)))=0,IF(MOD(O10,1)<=TIME(8,15,0),"Ingreso adecuado primera hora","Atraso primera hora"),"No aplica")),"") | U10: =IFERROR(VLOOKUP(M10,'Horario Pabellones'!$A$4:$D$17,2,FALSE),"") | V10: =IFERROR(VLOOKUP(M10,'Horario Pabellones'!$A$4:$D$17,3,FALSE),"") | W10: =IFERROR(VLOOKUP(M10,'Horario Pabellones'!$A$4:$D$17,4,FALSE),"") | X10: =IFERROR(IF(OR(A10="",M10="",W10=""),"",(((_xludf.AGGREGATE(14,6,MOD($S$4:$S$500,1)/(($A$4:$A$500=A10)*($M$4:$M$500=M10)*($R$4:$R$500<>"")*($S$4:$S$500<>"")),1)-_xludf.AGGREGATE(15,6,MOD($R$4:$R$500,1)/(($A$4:$A$500=A10)*($M$4:$M$500=M10)*($R$4:$R$500<>"")*($S$4:$S$500<>"")),1))*1440)/60)/(W10/60)),"") | Y10: =IFERROR(IF(OR(O10="",A10="",M10=""),"",(IF(ISNUMBER(O10),MOD(O10,1),TIMEVALUE(O10))-LOOKUP(2,1/(($A$4:$A$500=A10)*($M$4:$M$500=M10)*($T$4:$T$500<>"")*($T$4:$T$500<IF(ISNUMBER(O10),MOD(O10,1),TIMEVALUE(O10)))),$T$4:$T$500))*1440),"") | Z10: =IFERROR(IF(Y10="","",IF(ROUND(Y10,0)<=15,"Cumple","No cumple")),"") | AB10: =IFERROR(IF(OR(O10="",R10=""),"",IF(IF(ISNUMBER(R10),MOD(R10,1),TIMEVALUE(R10))>=IF(ISNUMBER(O10),MOD(O10,1),TIMEVALUE(O10)),(IF(ISNUMBER(R10),MOD(R10,1),TIMEVALUE(R10))-IF(ISNUMBER(O10),MOD(O10,1),TIMEVALUE(O10)))*1440,(IF(ISNUMBER(R10),MOD(R10,1),TIMEVALUE(R10))+1-IF(ISNUMBER(O10),MOD(O10,1),TIMEVALUE(O10)))*1440)),"") | AC10: =IFERROR(IF(OR(R10="",S10=""),"",IF(IF(ISNUMBER(S10),MOD(S10,1),TIMEVALUE(S10))>=IF(ISNUMBER(R10),MOD(R10,1),TIMEVALUE(R10)),(IF(ISNUMBER(S10),MOD(S10,1),TIMEVALUE(S10))-IF(ISNUMBER(R10),MOD(R10,1),TIMEVALUE(R10)))*1440,(IF(ISNUMBER(S10),MOD(S10,1),TIMEVALUE(S10))+1-IF(ISNUMBER(R10),MOD(R10,1),TIMEVALUE(R10)))*1440)),"") | AE10: =IFERROR(IF(OR(AC10="",AD10=""),"",AC10-AD10),"") | AF10: =IFERROR(IF(AE10="","",IF(ROUND(AE10,0)>15,"Subestimacion",IF(ROUND(AE10,0)<-15,"Sobrestimacion","Asertivo"))),"") | AP10: =IF(A10="","",A10-WEEKDAY(A10,2)+1) | AQ10: =IF(AO10="","",AO10+6) | AR10: =IF(AO10="","","Semana "&TEXT(AO10,"dd-mm-yyyy")&" al "&TEXT(AP10,"dd-mm-yyyy")) | AS10: =IF(A10="","",TEXT(A10,"mmmm yyyy")) | AT10: =IF(A10="","",TEXT(A10,"dddd")) | AU10: =IF(A10="","","CRR-"&TEXT(A10,"yyyymmdd")&"-"&M10&"-"&TEXT(ROW()-3,"0000")) | AV10: =IF(A10="","",IF(OR(B10="",C10="",E10="",F10="",M10="",N10=""),"Revisar campos obligatorios",IF(AND(P10="Atraso primera hora",Q10=""),"Falta justificación atraso primera hora",IF(AND(Z10="No cumple",AA10=""),"Falta justificación recambio >15 min",IF(AND(ISNUMBER(SEARCH("suspend",N10)),OR(AG10="",AH10="")),"Falta causa/motivo suspensión","OK"))))) | AW10: =IF(N10="","",IF(ISNUMBER(SEARCH("suspend",N10)),IF(AND(AG10="",AH10=""),"Sin causa/motivo registrado",IF(AG10="",AH10,IF(AH10="",AG10,AG10&": "&AH10))),""))
J11: =IF(H11<>"",IFERROR(VLOOKUP(IFERROR(LEFT(H11,FIND("-",H11)-1),H11),'Catalogo MINSAL'!A:E,5,FALSE),""),IF(I11<>"",IFERROR(VLOOKUP(IFERROR(LEFT(I11,FIND("-",I11)-1),I11),'Catalogo MINSAL'!A:E,5,FALSE),""),"")) | P11: =IFERROR(IF(OR(O11="",A11="",M11=""),"",IF(SUMPRODUCT(($A$4:$A$500=A11)*($M$4:$M$500=M11)*($O$4:$O$500<>"")*(MOD($O$4:$O$500,1)<MOD(O11,1)))=0,IF(MOD(O11,1)<=TIME(8,15,0),"Ingreso adecuado primera hora","Atraso primera hora"),"No aplica")),"") | U11: =IFERROR(VLOOKUP(M11,'Horario Pabellones'!$A$4:$D$17,2,FALSE),"") | V11: =IFERROR(VLOOKUP(M11,'Horario Pabellones'!$A$4:$D$17,3,FALSE),"") | W11: =IFERROR(VLOOKUP(M11,'Horario Pabellones'!$A$4:$D$17,4,FALSE),"") | X11: =IFERROR(IF(OR(A11="",M11="",W11=""),"",(((_xludf.AGGREGATE(14,6,MOD($S$4:$S$500,1)/(($A$4:$A$500=A11)*($M$4:$M$500=M11)*($R$4:$R$500<>"")*($S$4:$S$500<>"")),1)-_xludf.AGGREGATE(15,6,MOD($R$4:$R$500,1)/(($A$4:$A$500=A11)*($M$4:$M$500=M11)*($R$4:$R$500<>"")*($S$4:$S$500<>"")),1))*1440)/60)/(W11/60)),"") | Y11: =IFERROR(IF(OR(O11="",A11="",M11=""),"",(IF(ISNUMBER(O11),MOD(O11,1),TIMEVALUE(O11))-LOOKUP(2,1/(($A$4:$A$500=A11)*($M$4:$M$500=M11)*($T$4:$T$500<>"")*($T$4:$T$500<IF(ISNUMBER(O11),MOD(O11,1),TIMEVALUE(O11)))),$T$4:$T$500))*1440),"") | Z11: =IFERROR(IF(Y11="","",IF(ROUND(Y11,0)<=15,"Cumple","No cumple")),"") | AB11: =IFERROR(IF(OR(O11="",R11=""),"",IF(IF(ISNUMBER(R11),MOD(R11,1),TIMEVALUE(R11))>=IF(ISNUMBER(O11),MOD(O11,1),TIMEVALUE(O11)),(IF(ISNUMBER(R11),MOD(R11,1),TIMEVALUE(R11))-IF(ISNUMBER(O11),MOD(O11,1),TIMEVALUE(O11)))*1440,(IF(ISNUMBER(R11),MOD(R11,1),TIMEVALUE(R11))+1-IF(ISNUMBER(O11),MOD(O11,1),TIMEVALUE(O11)))*1440)),"") | AC11: =IFERROR(IF(OR(R11="",S11=""),"",IF(IF(ISNUMBER(S11),MOD(S11,1),TIMEVALUE(S11))>=IF(ISNUMBER(R11),MOD(R11,1),TIMEVALUE(R11)),(IF(ISNUMBER(S11),MOD(S11,1),TIMEVALUE(S11))-IF(ISNUMBER(R11),MOD(R11,1),TIMEVALUE(R11)))*1440,(IF(ISNUMBER(S11),MOD(S11,1),TIMEVALUE(S11))+1-IF(ISNUMBER(R11),MOD(R11,1),TIMEVALUE(R11)))*1440)),"") | AE11: =IFERROR(IF(OR(AC11="",AD11=""),"",AC11-AD11),"") | AF11: =IFERROR(IF(AE11="","",IF(ROUND(AE11,0)>15,"Subestimacion",IF(ROUND(AE11,0)<-15,"Sobrestimacion","Asertivo"))),"") | AP11: =IF(A11="","",A11-WEEKDAY(A11,2)+1) | AQ11: =IF(AO11="","",AO11+6) | AR11: =IF(AO11="","","Semana "&TEXT(AO11,"dd-mm-yyyy")&" al "&TEXT(AP11,"dd-mm-yyyy")) | AS11: =IF(A11="","",TEXT(A11,"mmmm yyyy")) | AT11: =IF(A11="","",TEXT(A11,"dddd")) | AU11: =IF(A11="","","CRR-"&TEXT(A11,"yyyymmdd")&"-"&M11&"-"&TEXT(ROW()-3,"0000")) | AV11: =IF(A11="","",IF(OR(B11="",C11="",E11="",F11="",M11="",N11=""),"Revisar campos obligatorios",IF(AND(P11="Atraso primera hora",Q11=""),"Falta justificación atraso primera hora",IF(AND(Z11="No cumple",AA11=""),"Falta justificación recambio >15 min",IF(AND(ISNUMBER(SEARCH("suspend",N11)),OR(AG11="",AH11="")),"Falta causa/motivo suspensión","OK"))))) | AW11: =IF(N11="","",IF(ISNUMBER(SEARCH("suspend",N11)),IF(AND(AG11="",AH11=""),"Sin causa/motivo registrado",IF(AG11="",AH11,IF(AH11="",AG11,AG11&": "&AH11))),""))
J12: =IF(H12<>"",IFERROR(VLOOKUP(IFERROR(LEFT(H12,FIND("-",H12)-1),H12),'Catalogo MINSAL'!A:E,5,FALSE),""),IF(I12<>"",IFERROR(VLOOKUP(IFERROR(LEFT(I12,FIND("-",I12)-1),I12),'Catalogo MINSAL'!A:E,5,FALSE),""),"")) | P12: =IFERROR(IF(OR(O12="",A12="",M12=""),"",IF(SUMPRODUCT(($A$4:$A$500=A12)*($M$4:$M$500=M12)*($O$4:$O$500<>"")*(MOD($O$4:$O$500,1)<MOD(O12,1)))=0,IF(MOD(O12,1)<=TIME(8,15,0),"Ingreso adecuado primera hora","Atraso primera hora"),"No aplica")),"") | U12: =IFERROR(VLOOKUP(M12,'Horario Pabellones'!$A$4:$D$17,2,FALSE),"") | V12: =IFERROR(VLOOKUP(M12,'Horario Pabellones'!$A$4:$D$17,3,FALSE),"") | W12: =IFERROR(VLOOKUP(M12,'Horario Pabellones'!$A$4:$D$17,4,FALSE),"") | X12: =IFERROR(IF(OR(A12="",M12="",W12=""),"",(((_xludf.AGGREGATE(14,6,MOD($S$4:$S$500,1)/(($A$4:$A$500=A12)*($M$4:$M$500=M12)*($R$4:$R$500<>"")*($S$4:$S$500<>"")),1)-_xludf.AGGREGATE(15,6,MOD($R$4:$R$500,1)/(($A$4:$A$500=A12)*($M$4:$M$500=M12)*($R$4:$R$500<>"")*($S$4:$S$500<>"")),1))*1440)/60)/(W12/60)),"") | Y12: =IFERROR(IF(OR(O12="",A12="",M12=""),"",(IF(ISNUMBER(O12),MOD(O12,1),TIMEVALUE(O12))-LOOKUP(2,1/(($A$4:$A$500=A12)*($M$4:$M$500=M12)*($T$4:$T$500<>"")*($T$4:$T$500<IF(ISNUMBER(O12),MOD(O12,1),TIMEVALUE(O12)))),$T$4:$T$500))*1440),"") | Z12: =IFERROR(IF(Y12="","",IF(ROUND(Y12,0)<=15,"Cumple","No cumple")),"") | AB12: =IFERROR(IF(OR(O12="",R12=""),"",IF(IF(ISNUMBER(R12),MOD(R12,1),TIMEVALUE(R12))>=IF(ISNUMBER(O12),MOD(O12,1),TIMEVALUE(O12)),(IF(ISNUMBER(R12),MOD(R12,1),TIMEVALUE(R12))-IF(ISNUMBER(O12),MOD(O12,1),TIMEVALUE(O12)))*1440,(IF(ISNUMBER(R12),MOD(R12,1),TIMEVALUE(R12))+1-IF(ISNUMBER(O12),MOD(O12,1),TIMEVALUE(O12)))*1440)),"") | AC12: =IFERROR(IF(OR(R12="",S12=""),"",IF(IF(ISNUMBER(S12),MOD(S12,1),TIMEVALUE(S12))>=IF(ISNUMBER(R12),MOD(R12,1),TIMEVALUE(R12)),(IF(ISNUMBER(S12),MOD(S12,1),TIMEVALUE(S12))-IF(ISNUMBER(R12),MOD(R12,1),TIMEVALUE(R12)))*1440,(IF(ISNUMBER(S12),MOD(S12,1),TIMEVALUE(S12))+1-IF(ISNUMBER(R12),MOD(R12,1),TIMEVALUE(R12)))*1440)),"") | AE12: =IFERROR(IF(OR(AC12="",AD12=""),"",AC12-AD12),"") | AF12: =IFERROR(IF(AE12="","",IF(ROUND(AE12,0)>15,"Subestimacion",IF(ROUND(AE12,0)<-15,"Sobrestimacion","Asertivo"))),"") | AP12: =IF(A12="","",A12-WEEKDAY(A12,2)+1) | AQ12: =IF(AO12="","",AO12+6) | AR12: =IF(AO12="","","Semana "&TEXT(AO12,"dd-mm-yyyy")&" al "&TEXT(AP12,"dd-mm-yyyy")) | AS12: =IF(A12="","",TEXT(A12,"mmmm yyyy")) | AT12: =IF(A12="","",TEXT(A12,"dddd")) | AU12: =IF(A12="","","CRR-"&TEXT(A12,"yyyymmdd")&"-"&M12&"-"&TEXT(ROW()-3,"0000")) | AV12: =IF(A12="","",IF(OR(B12="",C12="",E12="",F12="",M12="",N12=""),"Revisar campos obligatorios",IF(AND(P12="Atraso primera hora",Q12=""),"Falta justificación atraso primera hora",IF(AND(Z12="No cumple",AA12=""),"Falta justificación recambio >15 min",IF(AND(ISNUMBER(SEARCH("suspend",N12)),OR(AG12="",AH12="")),"Falta causa/motivo suspensión","OK"))))) | AW12: =IF(N12="","",IF(ISNUMBER(SEARCH("suspend",N12)),IF(AND(AG12="",AH12=""),"Sin causa/motivo registrado",IF(AG12="",AH12,IF(AH12="",AG12,AG12&": "&AH12))),""))
J13: =IF(H13<>"",IFERROR(VLOOKUP(IFERROR(LEFT(H13,FIND("-",H13)-1),H13),'Catalogo MINSAL'!A:E,5,FALSE),""),IF(I13<>"",IFERROR(VLOOKUP(IFERROR(LEFT(I13,FIND("-",I13)-1),I13),'Catalogo MINSAL'!A:E,5,FALSE),""),"")) | P13: =IFERROR(IF(OR(O13="",A13="",M13=""),"",IF(SUMPRODUCT(($A$4:$A$500=A13)*($M$4:$M$500=M13)*($O$4:$O$500<>"")*(MOD($O$4:$O$500,1)<MOD(O13,1)))=0,IF(MOD(O13,1)<=TIME(8,15,0),"Ingreso adecuado primera hora","Atraso primera hora"),"No aplica")),"") | U13: =IFERROR(VLOOKUP(M13,'Horario Pabellones'!$A$4:$D$17,2,FALSE),"") | V13: =IFERROR(VLOOKUP(M13,'Horario Pabellones'!$A$4:$D$17,3,FALSE),"") | W13: =IFERROR(VLOOKUP(M13,'Horario Pabellones'!$A$4:$D$17,4,FALSE),"") | X13: =IFERROR(IF(OR(A13="",M13="",W13=""),"",(((_xludf.AGGREGATE(14,6,MOD($S$4:$S$500,1)/(($A$4:$A$500=A13)*($M$4:$M$500=M13)*($R$4:$R$500<>"")*($S$4:$S$500<>"")),1)-_xludf.AGGREGATE(15,6,MOD($R$4:$R$500,1)/(($A$4:$A$500=A13)*($M$4:$M$500=M13)*($R$4:$R$500<>"")*($S$4:$S$500<>"")),1))*1440)/60)/(W13/60)),"") | Y13: =IFERROR(IF(OR(O13="",A13="",M13=""),"",(IF(ISNUMBER(O13),MOD(O13,1),TIMEVALUE(O13))-LOOKUP(2,1/(($A$4:$A$500=A13)*($M$4:$M$500=M13)*($T$4:$T$500<>"")*($T$4:$T$500<IF(ISNUMBER(O13),MOD(O13,1),TIMEVALUE(O13)))),$T$4:$T$500))*1440),"") | Z13: =IFERROR(IF(Y13="","",IF(ROUND(Y13,0)<=15,"Cumple","No cumple")),"") | AB13: =IFERROR(IF(OR(O13="",R13=""),"",IF(IF(ISNUMBER(R13),MOD(R13,1),TIMEVALUE(R13))>=IF(ISNUMBER(O13),MOD(O13,1),TIMEVALUE(O13)),(IF(ISNUMBER(R13),MOD(R13,1),TIMEVALUE(R13))-IF(ISNUMBER(O13),MOD(O13,1),TIMEVALUE(O13)))*1440,(IF(ISNUMBER(R13),MOD(R13,1),TIMEVALUE(R13))+1-IF(ISNUMBER(O13),MOD(O13,1),TIMEVALUE(O13)))*1440)),"") | AC13: =IFERROR(IF(OR(R13="",S13=""),"",IF(IF(ISNUMBER(S13),MOD(S13,1),TIMEVALUE(S13))>=IF(ISNUMBER(R13),MOD(R13,1),TIMEVALUE(R13)),(IF(ISNUMBER(S13),MOD(S13,1),TIMEVALUE(S13))-IF(ISNUMBER(R13),MOD(R13,1),TIMEVALUE(R13)))*1440,(IF(ISNUMBER(S13),MOD(S13,1),TIMEVALUE(S13))+1-IF(ISNUMBER(R13),MOD(R13,1),TIMEVALUE(R13)))*1440)),"") | AE13: =IFERROR(IF(OR(AC13="",AD13=""),"",AC13-AD13),"") | AF13: =IFERROR(IF(AE13="","",IF(ROUND(AE13,0)>15,"Subestimacion",IF(ROUND(AE13,0)<-15,"Sobrestimacion","Asertivo"))),"") | AP13: =IF(A13="","",A13-WEEKDAY(A13,2)+1) | AQ13: =IF(AO13="","",AO13+6) | AR13: =IF(AO13="","","Semana "&TEXT(AO13,"dd-mm-yyyy")&" al "&TEXT(AP13,"dd-mm-yyyy")) | AS13: =IF(A13="","",TEXT(A13,"mmmm yyyy")) | AT13: =IF(A13="","",TEXT(A13,"dddd")) | AU13: =IF(A13="","","CRR-"&TEXT(A13,"yyyymmdd")&"-"&M13&"-"&TEXT(ROW()-3,"0000")) | AV13: =IF(A13="","",IF(OR(B13="",C13="",E13="",F13="",M13="",N13=""),"Revisar campos obligatorios",IF(AND(P13="Atraso primera hora",Q13=""),"Falta justificación atraso primera hora",IF(AND(Z13="No cumple",AA13=""),"Falta justificación recambio >15 min",IF(AND(ISNUMBER(SEARCH("suspend",N13)),OR(AG13="",AH13="")),"Falta causa/motivo suspensión","OK"))))) | AW13: =IF(N13="","",IF(ISNUMBER(SEARCH("suspend",N13)),IF(AND(AG13="",AH13=""),"Sin causa/motivo registrado",IF(AG13="",AH13,IF(AH13="",AG13,AG13&": "&AH13))),""))
A14: 46167 | B14: DIEGO ANDRES | C14: GONZALEZ | D14: 16a 0m 25d | E14: FRACTURA O PSEUDOARTROSIS ESCAFOIDES, TRAT. QUIR. CUALQ. TECN. | F14: SERVICIO DE TRAUMATOLOGIA | H14: 2104081-5 | J14: =IF(H14<>"",IFERROR(VLOOKUP(IFERROR(LEFT(H14,FIND("-",H14)-1),H14),'Catalogo MINSAL'!A:E,5,FALSE),""),IF(I14<>"",IFERROR(VLOOKUP(IFERROR(LEFT(I14,FIND("-",I14)-1),I14),'Catalogo MINSAL'!A:E,5,FALSE),""),"")) | K14: ALVARO RIDERELLI SANCHEZ | L14: Dr. Alexis Arredondo Torrales | M14: Quirofano 11 | N14: Atendido | O14: 0.36111111 | P14: =IFERROR(IF(OR(O14="",A14="",M14=""),"",IF(SUMPRODUCT(($A$4:$A$500=A14)*($M$4:$M$500=M14)*($O$4:$O$500<>"")*(MOD($O$4:$O$500,1)<MOD(O14,1)))=0,IF(MOD(O14,1)<=TIME(8,15,0),"Ingreso adecuado primera hora","Atraso primera hora"),"No aplica")),"") | R14: 0.38194444 | S14: 0.41666667 | T14: 0.42361111 | U14: =IFERROR(VLOOKUP(M14,'Horario Pabellones'!$A$4:$D$17,2,FALSE),"") | V14: =IFERROR(VLOOKUP(M14,'Horario Pabellones'!$A$4:$D$17,3,FALSE),"") | W14: =IFERROR(VLOOKUP(M14,'Horario Pabellones'!$A$4:$D$17,4,FALSE),"") | X14: =IFERROR(IF(OR(A14="",M14="",W14=""),"",(((_xludf.AGGREGATE(14,6,MOD($S$4:$S$500,1)/(($A$4:$A$500=A14)*($M$4:$M$500=M14)*($R$4:$R$500<>"")*($S$4:$S$500<>"")),1)-_xludf.AGGREGATE(15,6,MOD($R$4:$R$500,1)/(($A$4:$A$500=A14)*($M$4:$M$500=M14)*($R$4:$R$500<>"")*($S$4:$S$500<>"")),1))*1440)/60)/(W14/60)),"") | Y14: =IFERROR(IF(OR(O14="",A14="",M14=""),"",(IF(ISNUMBER(O14),MOD(O14,1),TIMEVALUE(O14))-LOOKUP(2,1/(($A$4:$A$500=A14)*($M$4:$M$500=M14)*($T$4:$T$500<>"")*($T$4:$T$500<IF(ISNUMBER(O14),MOD(O14,1),TIMEVALUE(O14)))),$T$4:$T$500))*1440),"") | Z14: =IFERROR(IF(Y14="","",IF(ROUND(Y14,0)<=15,"Cumple","No cumple")),"") | AB14: =IFERROR(IF(OR(O14="",R14=""),"",IF(IF(ISNUMBER(R14),MOD(R14,1),TIMEVALUE(R14))>=IF(ISNUMBER(O14),MOD(O14,1),TIMEVALUE(O14)),(IF(ISNUMBER(R14),MOD(R14,1),TIMEVALUE(R14))-IF(ISNUMBER(O14),MOD(O14,1),TIMEVALUE(O14)))*1440,(IF(ISNUMBER(R14),MOD(R14,1),TIMEVALUE(R14))+1-IF(ISNUMBER(O14),MOD(O14,1),TIMEVALUE(O14)))*1440)),"") | AC14: =IFERROR(IF(OR(R14="",S14=""),"",IF(IF(ISNUMBER(S14),MOD(S14,1),TIMEVALUE(S14))>=IF(ISNUMBER(R14),MOD(R14,1),TIMEVALUE(R14)),(IF(ISNUMBER(S14),MOD(S14,1),TIMEVALUE(S14))-IF(ISNUMBER(R14),MOD(R14,1),TIMEVALUE(R14)))*1440,(IF(ISNUMBER(S14),MOD(S14,1),TIMEVALUE(S14))+1-IF(ISNUMBER(R14),MOD(R14,1),TIMEVALUE(R14)))*1440)),"") | AD14: 90 | AE14: =IFERROR(IF(OR(AC14="",AD14=""),"",AC14-AD14),"") | AF14: =IFERROR(IF(AE14="","",IF(ROUND(AE14,0)>15,"Subestimacion",IF(ROUND(AE14,0)<-15,"Sobrestimacion","Asertivo"))),"") | AG14: Sin Suspensión | AM14: I0001187219 | AP14: =IF(A14="","",A14-WEEKDAY(A14,2)+1) | AQ14: =IF(AO14="","",AO14+6) | AR14: =IF(AO14="","","Semana "&TEXT(AO14,"dd-mm-yyyy")&" al "&TEXT(AP14,"dd-mm-yyyy")) | AS14: =IF(A14="","",TEXT(A14,"mmmm yyyy")) | AT14: =IF(A14="","",TEXT(A14,"dddd")) | AU14: =IF(A14="","","CRR-"&TEXT(A14,"yyyymmdd")&"-"&M14&"-"&TEXT(ROW()-3,"0000")) | AV14: =IF(A14="","",IF(OR(B14="",C14="",E14="",F14="",M14="",N14=""),"Revisar campos obligatorios",IF(AND(P14="Atraso primera hora",Q14=""),"Falta justificación atraso primera hora",IF(AND(Z14="No cumple",AA14=""),"Falta justificación recambio >15 min",IF(AND(ISNUMBER(SEARCH("suspend",N14)),OR(AG14="",AH14="")),"Falta causa/motivo suspensión","OK"))))) | AW14: =IF(N14="","",IF(ISNUMBER(SEARCH("suspend",N14)),IF(AND(AG14="",AH14=""),"Sin causa/motivo registrado",IF(AG14="",AH14,IF(AH14="",AG14,AG14&": "&AH14))),""))
A15: 46167 | B15: MÓNICA DEL CARMEN | C15: ROJAS | D15: 57a 11m 0d | E15: OSTEOSINTESIS RADIO, (CUALQUIER TECNICA) | F15: SERVICIO DE TRAUMATOLOGIA | H15: 2104085-6 | J15: =IF(H15<>"",IFERROR(VLOOKUP(IFERROR(LEFT(H15,FIND("-",H15)-1),H15),'Catalogo MINSAL'!A:E,5,FALSE),""),IF(I15<>"",IFERROR(VLOOKUP(IFERROR(LEFT(I15,FIND("-",I15)-1),I15),'Catalogo MINSAL'!A:E,5,FALSE),""),"")) | K15: ALVARO RIDERELLI SANCHEZ | L15: Dr. Alexis Arredondo Torrales | M15: Quirofano 11 | N15: Atendido | O15: 0.4375 | P15: =IFERROR(IF(OR(O15="",A15="",M15=""),"",IF(SUMPRODUCT(($A$4:$A$500=A15)*($M$4:$M$500=M15)*($O$4:$O$500<>"")*(MOD($O$4:$O$500,1)<MOD(O15,1)))=0,IF(MOD(O15,1)<=TIME(8,15,0),"Ingreso adecuado primera hora","Atraso primera hora"),"No aplica")),"") | R15: 0.46666667 | S15: 0.53472222 | T15: 0.54861111 | U15: =IFERROR(VLOOKUP(M15,'Horario Pabellones'!$A$4:$D$17,2,FALSE),"") | V15: =IFERROR(VLOOKUP(M15,'Horario Pabellones'!$A$4:$D$17,3,FALSE),"") | W15: =IFERROR(VLOOKUP(M15,'Horario Pabellones'!$A$4:$D$17,4,FALSE),"") | X15: =IFERROR(IF(OR(A15="",M15="",W15=""),"",(((_xludf.AGGREGATE(14,6,MOD($S$4:$S$500,1)/(($A$4:$A$500=A15)*($M$4:$M$500=M15)*($R$4:$R$500<>"")*($S$4:$S$500<>"")),1)-_xludf.AGGREGATE(15,6,MOD($R$4:$R$500,1)/(($A$4:$A$500=A15)*($M$4:$M$500=M15)*($R$4:$R$500<>"")*($S$4:$S$500<>"")),1))*1440)/60)/(W15/60)),"") | Y15: =IFERROR(IF(OR(O15="",A15="",M15=""),"",(IF(ISNUMBER(O15),MOD(O15,1),TIMEVALUE(O15))-LOOKUP(2,1/(($A$4:$A$500=A15)*($M$4:$M$500=M15)*($T$4:$T$500<>"")*($T$4:$T$500<IF(ISNUMBER(O15),MOD(O15,1),TIMEVALUE(O15)))),$T$4:$T$500))*1440),"") | Z15: =IFERROR(IF(Y15="","",IF(ROUND(Y15,0)<=15,"Cumple","No cumple")),"") | AB15: =IFERROR(IF(OR(O15="",R15=""),"",IF(IF(ISNUMBER(R15),MOD(R15,1),TIMEVALUE(R15))>=IF(ISNUMBER(O15),MOD(O15,1),TIMEVALUE(O15)),(IF(ISNUMBER(R15),MOD(R15,1),TIMEVALUE(R15))-IF(ISNUMBER(O15),MOD(O15,1),TIMEVALUE(O15)))*1440,(IF(ISNUMBER(R15),MOD(R15,1),TIMEVALUE(R15))+1-IF(ISNUMBER(O15),MOD(O15,1),TIMEVALUE(O15)))*1440)),"") | AC15: =IFERROR(IF(OR(R15="",S15=""),"",IF(IF(ISNUMBER(S15),MOD(S15,1),TIMEVALUE(S15))>=IF(ISNUMBER(R15),MOD(R15,1),TIMEVALUE(R15)),(IF(ISNUMBER(S15),MOD(S15,1),TIMEVALUE(S15))-IF(ISNUMBER(R15),MOD(R15,1),TIMEVALUE(R15)))*1440,(IF(ISNUMBER(S15),MOD(S15,1),TIMEVALUE(S15))+1-IF(ISNUMBER(R15),MOD(R15,1),TIMEVALUE(R15)))*1440)),"") | AD15: 60 | AE15: =IFERROR(IF(OR(AC15="",AD15=""),"",AC15-AD15),"") | AF15: =IFERROR(IF(AE15="","",IF(ROUND(AE15,0)>15,"Subestimacion",IF(ROUND(AE15,0)<-15,"Sobrestimacion","Asertivo"))),"") | AG15: Sin Suspensión | AM15: I0001187220 | AP15: =IF(A15="","",A15-WEEKDAY(A15,2)+1) | AQ15: =IF(AO15="","",AO15+6) | AR15: =IF(AO15="","","Semana "&TEXT(AO15,"dd-mm-yyyy")&" al "&TEXT(AP15,"dd-mm-yyyy")) | AS15: =IF(A15="","",TEXT(A15,"mmmm yyyy")) | AT15: =IF(A15="","",TEXT(A15,"dddd")) | AU15: =IF(A15="","","CRR-"&TEXT(A15,"yyyymmdd")&"-"&M15&"-"&TEXT(ROW()-3,"0000")) | AV15: =IF(A15="","",IF(OR(B15="",C15="",E15="",F15="",M15="",N15=""),"Revisar campos obligatorios",IF(AND(P15="Atraso primera hora",Q15=""),"Falta justificación atraso primera hora",IF(AND(Z15="No cumple",AA15=""),"Falta justificación recambio >15 min",IF(AND(ISNUMBER(SEARCH("suspend",N15)),OR(AG15="",AH15="")),"Falta causa/motivo suspensión","OK"))))) | AW15: =IF(N15="","",IF(ISNUMBER(SEARCH("suspend",N15)),IF(AND(AG15="",AH15=""),"Sin causa/motivo registrado",IF(AG15="",AH15,IF(AH15="",AG15,AG15&": "&AH15))),""))
A16: 46167 | B16: JOSÉ JAIME | C16: BARRIENTOS | D16: 64a 11m 14d | E16: OSTEOSINTESIS METACARPIANAS O DE FALANGES, CUALQUIER TECNICA | F16: SERVICIO DE TRAUMATOLOGIA | H16: 2104099-4 | J16: =IF(H16<>"",IFERROR(VLOOKUP(IFERROR(LEFT(H16,FIND("-",H16)-1),H16),'Catalogo MINSAL'!A:E,5,FALSE),""),IF(I16<>"",IFERROR(VLOOKUP(IFERROR(LEFT(I16,FIND("-",I16)-1),I16),'Catalogo MINSAL'!A:E,5,FALSE),""),"")) | K16: ALVARO RIDERELLI SANCHEZ | L16: Dr. Alexis Arredondo Torrales | M16: Quirofano 11 | N16: Atendido | O16: 0.57638889 | P16: =IFERROR(IF(OR(O16="",A16="",M16=""),"",IF(SUMPRODUCT(($A$4:$A$500=A16)*($M$4:$M$500=M16)*($O$4:$O$500<>"")*(MOD($O$4:$O$500,1)<MOD(O16,1)))=0,IF(MOD(O16,1)<=TIME(8,15,0),"Ingreso adecuado primera hora","Atraso primera hora"),"No aplica")),"") | R16: 0.60416667 | S16: 0.66666667 | T16: 0.67013889 | U16: =IFERROR(VLOOKUP(M16,'Horario Pabellones'!$A$4:$D$17,2,FALSE),"") | V16: =IFERROR(VLOOKUP(M16,'Horario Pabellones'!$A$4:$D$17,3,FALSE),"") | W16: =IFERROR(VLOOKUP(M16,'Horario Pabellones'!$A$4:$D$17,4,FALSE),"") | X16: =IFERROR(IF(OR(A16="",M16="",W16=""),"",(((_xludf.AGGREGATE(14,6,MOD($S$4:$S$500,1)/(($A$4:$A$500=A16)*($M$4:$M$500=M16)*($R$4:$R$500<>"")*($S$4:$S$500<>"")),1)-_xludf.AGGREGATE(15,6,MOD($R$4:$R$500,1)/(($A$4:$A$500=A16)*($M$4:$M$500=M16)*($R$4:$R$500<>"")*($S$4:$S$500<>"")),1))*1440)/60)/(W16/60)),"") | Y16: =IFERROR(IF(OR(O16="",A16="",M16=""),"",(IF(ISNUMBER(O16),MOD(O16,1),TIMEVALUE(O16))-LOOKUP(2,1/(($A$4:$A$500=A16)*($M$4:$M$500=M16)*($T$4:$T$500<>"")*($T$4:$T$500<IF(ISNUMBER(O16),MOD(O16,1),TIMEVALUE(O16)))),$T$4:$T$500))*1440),"") | Z16: =IFERROR(IF(Y16="","",IF(ROUND(Y16,0)<=15,"Cumple","No cumple")),"") | AB16: =IFERROR(IF(OR(O16="",R16=""),"",IF(IF(ISNUMBER(R16),MOD(R16,1),TIMEVALUE(R16))>=IF(ISNUMBER(O16),MOD(O16,1),TIMEVALUE(O16)),(IF(ISNUMBER(R16),MOD(R16,1),TIMEVALUE(R16))-IF(ISNUMBER(O16),MOD(O16,1),TIMEVALUE(O16)))*1440,(IF(ISNUMBER(R16),MOD(R16,1),TIMEVALUE(R16))+1-IF(ISNUMBER(O16),MOD(O16,1),TIMEVALUE(O16)))*1440)),"") | AC16: =IFERROR(IF(OR(R16="",S16=""),"",IF(IF(ISNUMBER(S16),MOD(S16,1),TIMEVALUE(S16))>=IF(ISNUMBER(R16),MOD(R16,1),TIMEVALUE(R16)),(IF(ISNUMBER(S16),MOD(S16,1),TIMEVALUE(S16))-IF(ISNUMBER(R16),MOD(R16,1),TIMEVALUE(R16)))*1440,(IF(ISNUMBER(S16),MOD(S16,1),TIMEVALUE(S16))+1-IF(ISNUMBER(R16),MOD(R16,1),TIMEVALUE(R16)))*1440)),"") | AD16: 90 | AE16: =IFERROR(IF(OR(AC16="",AD16=""),"",AC16-AD16),"") | AF16: =IFERROR(IF(AE16="","",IF(ROUND(AE16,0)>15,"Subestimacion",IF(ROUND(AE16,0)<-15,"Sobrestimacion","Asertivo"))),"") | AG16: Sin Suspensión | AM16: I0001187212 | AP16: =IF(A16="","",A16-WEEKDAY(A16,2)+1) | AQ16: =IF(AO16="","",AO16+6) | AR16: =IF(AO16="","","Semana "&TEXT(AO16,"dd-mm-yyyy")&" al "&TEXT(AP16,"dd-mm-yyyy")) | AS16: =IF(A16="","",TEXT(A16,"mmmm yyyy")) | AT16: =IF(A16="","",TEXT(A16,"dddd")) | AU16: =IF(A16="","","CRR-"&TEXT(A16,"yyyymmdd")&"-"&M16&"-"&TEXT(ROW()-3,"0000")) | AV16: =IF(A16="","",IF(OR(B16="",C16="",E16="",F16="",M16="",N16=""),"Revisar campos obligatorios",IF(AND(P16="Atraso primera hora",Q16=""),"Falta justificación atraso primera hora",IF(AND(Z16="No cumple",AA16=""),"Falta justificación recambio >15 min",IF(AND(ISNUMBER(SEARCH("suspend",N16)),OR(AG16="",AH16="")),"Falta causa/motivo suspensión","OK"))))) | AW16: =IF(N16="","",IF(ISNUMBER(SEARCH("suspend",N16)),IF(AND(AG16="",AH16=""),"Sin causa/motivo registrado",IF(AG16="",AH16,IF(AH16="",AG16,AG16&": "&AH16))),""))
A17: 46167 | B17: MARÍA ERCILIA | C17: MOLINA | D17: 72a 4m 15d | E17: RETIRO DE TORNILLOS, CLAVOS, AGUJAS DE OSTEOSINTESIS O SIMILARES | F17: SERVICIO DE TRAUMATOLOGIA | H17: 2106003-5 | J17: =IF(H17<>"",IFERROR(VLOOKUP(IFERROR(LEFT(H17,FIND("-",H17)-1),H17),'Catalogo MINSAL'!A:E,5,FALSE),""),IF(I17<>"",IFERROR(VLOOKUP(IFERROR(LEFT(I17,FIND("-",I17)-1),I17),'Catalogo MINSAL'!A:E,5,FALSE),""),"")) | K17: ALVARO RIDERELLI SANCHEZ | L17: Dr. Alexis Arredondo Torrales | M17: Quirofano 11 | N17: Atendido | O17: 0.70833333 | P17: =IFERROR(IF(OR(O17="",A17="",M17=""),"",IF(SUMPRODUCT(($A$4:$A$500=A17)*($M$4:$M$500=M17)*($O$4:$O$500<>"")*(MOD($O$4:$O$500,1)<MOD(O17,1)))=0,IF(MOD(O17,1)<=TIME(8,15,0),"Ingreso adecuado primera hora","Atraso primera hora"),"No aplica")),"") | R17: 0.72916667 | S17: 0.77083333 | T17: 0.77777778 | U17: =IFERROR(VLOOKUP(M17,'Horario Pabellones'!$A$4:$D$17,2,FALSE),"") | V17: =IFERROR(VLOOKUP(M17,'Horario Pabellones'!$A$4:$D$17,3,FALSE),"") | W17: =IFERROR(VLOOKUP(M17,'Horario Pabellones'!$A$4:$D$17,4,FALSE),"") | X17: =IFERROR(IF(OR(A17="",M17="",W17=""),"",(((_xludf.AGGREGATE(14,6,MOD($S$4:$S$500,1)/(($A$4:$A$500=A17)*($M$4:$M$500=M17)*($R$4:$R$500<>"")*($S$4:$S$500<>"")),1)-_xludf.AGGREGATE(15,6,MOD($R$4:$R$500,1)/(($A$4:$A$500=A17)*($M$4:$M$500=M17)*($R$4:$R$500<>"")*($S$4:$S$500<>"")),1))*1440)/60)/(W17/60)),"") | Y17: =IFERROR(IF(OR(O17="",A17="",M17=""),"",(IF(ISNUMBER(O17),MOD(O17,1),TIMEVALUE(O17))-LOOKUP(2,1/(($A$4:$A$500=A17)*($M$4:$M$500=M17)*($T$4:$T$500<>"")*($T$4:$T$500<IF(ISNUMBER(O17),MOD(O17,1),TIMEVALUE(O17)))),$T$4:$T$500))*1440),"") | Z17: =IFERROR(IF(Y17="","",IF(ROUND(Y17,0)<=15,"Cumple","No cumple")),"") | AB17: =IFERROR(IF(OR(O17="",R17=""),"",IF(IF(ISNUMBER(R17),MOD(R17,1),TIMEVALUE(R17))>=IF(ISNUMBER(O17),MOD(O17,1),TIMEVALUE(O17)),(IF(ISNUMBER(R17),MOD(R17,1),TIMEVALUE(R17))-IF(ISNUMBER(O17),MOD(O17,1),TIMEVALUE(O17)))*1440,(IF(ISNUMBER(R17),MOD(R17,1),TIMEVALUE(R17))+1-IF(ISNUMBER(O17),MOD(O17,1),TIMEVALUE(O17)))*1440)),"") | AC17: =IFERROR(IF(OR(R17="",S17=""),"",IF(IF(ISNUMBER(S17),MOD(S17,1),TIMEVALUE(S17))>=IF(ISNUMBER(R17),MOD(R17,1),TIMEVALUE(R17)),(IF(ISNUMBER(S17),MOD(S17,1),TIMEVALUE(S17))-IF(ISNUMBER(R17),MOD(R17,1),TIMEVALUE(R17)))*1440,(IF(ISNUMBER(S17),MOD(S17,1),TIMEVALUE(S17))+1-IF(ISNUMBER(R17),MOD(R17,1),TIMEVALUE(R17)))*1440)),"") | AD17: 60 | AE17: =IFERROR(IF(OR(AC17="",AD17=""),"",AC17-AD17),"") | AF17: =IFERROR(IF(AE17="","",IF(ROUND(AE17,0)>15,"Subestimacion",IF(ROUND(AE17,0)<-15,"Sobrestimacion","Asertivo"))),"") | AG17: Sin Suspensión | AM17: I0001187223 | AP17: =IF(A17="","",A17-WEEKDAY(A17,2)+1) | AQ17: =IF(AO17="","",AO17+6) | AR17: =IF(AO17="","","Semana "&TEXT(AO17,"dd-mm-yyyy")&" al "&TEXT(AP17,"dd-mm-yyyy")) | AS17: =IF(A17="","",TEXT(A17,"mmmm yyyy")) | AT17: =IF(A17="","",TEXT(A17,"dddd")) | AU17: =IF(A17="","","CRR-"&TEXT(A17,"yyyymmdd")&"-"&M17&"-"&TEXT(ROW()-3,"0000")) | AV17: =IF(A17="","",IF(OR(B17="",C17="",E17="",F17="",M17="",N17=""),"Revisar campos obligatorios",IF(AND(P17="Atraso primera hora",Q17=""),"Falta justificación atraso primera hora",IF(AND(Z17="No cumple",AA17=""),"Falta justificación recambio >15 min",IF(AND(ISNUMBER(SEARCH("suspend",N17)),OR(AG17="",AH17="")),"Falta causa/motivo suspensión","OK"))))) | AW17: =IF(N17="","",IF(ISNUMBER(SEARCH("suspend",N17)),IF(AND(AG17="",AH17=""),"Sin causa/motivo registrado",IF(AG17="",AH17,IF(AH17="",AG17,AG17&": "&AH17))),""))
A18: 46167 | B18: MARTÍN ALFONSO | C18: ASTUDILLO | D18: 22a 0m 0d | E18: OSTEOSINTESIS METACARPIANAS O DE FALANGES, CUALQUIER TECNICA | F18: SERVICIO DE TRAUMATOLOGIA | H18: 2104099-4 | J18: =IF(H18<>"",IFERROR(VLOOKUP(IFERROR(LEFT(H18,FIND("-",H18)-1),H18),'Catalogo MINSAL'!A:E,5,FALSE),""),IF(I18<>"",IFERROR(VLOOKUP(IFERROR(LEFT(I18,FIND("-",I18)-1),I18),'Catalogo MINSAL'!A:E,5,FALSE),""),"")) | L18: Dr. Alexis Arredondo Torrales | M18: Quirofano 11 | N18: Suspendido | P18: =IFERROR(IF(OR(O18="",A18="",M18=""),"",IF(SUMPRODUCT(($A$4:$A$500=A18)*($M$4:$M$500=M18)*($O$4:$O$500<>"")*(MOD($O$4:$O$500,1)<MOD(O18,1)))=0,IF(MOD(O18,1)<=TIME(8,15,0),"Ingreso adecuado primera hora","Atraso primera hora"),"No aplica")),"") | U18: =IFERROR(VLOOKUP(M18,'Horario Pabellones'!$A$4:$D$17,2,FALSE),"") | V18: =IFERROR(VLOOKUP(M18,'Horario Pabellones'!$A$4:$D$17,3,FALSE),"") | W18: =IFERROR(VLOOKUP(M18,'Horario Pabellones'!$A$4:$D$17,4,FALSE),"") | X18: =IFERROR(IF(OR(A18="",M18="",W18=""),"",(((_xludf.AGGREGATE(14,6,MOD($S$4:$S$500,1)/(($A$4:$A$500=A18)*($M$4:$M$500=M18)*($R$4:$R$500<>"")*($S$4:$S$500<>"")),1)-_xludf.AGGREGATE(15,6,MOD($R$4:$R$500,1)/(($A$4:$A$500=A18)*($M$4:$M$500=M18)*($R$4:$R$500<>"")*($S$4:$S$500<>"")),1))*1440)/60)/(W18/60)),"") | Y18: =IFERROR(IF(OR(O18="",A18="",M18=""),"",(IF(ISNUMBER(O18),MOD(O18,1),TIMEVALUE(O18))-LOOKUP(2,1/(($A$4:$A$500=A18)*($M$4:$M$500=M18)*($T$4:$T$500<>"")*($T$4:$T$500<IF(ISNUMBER(O18),MOD(O18,1),TIMEVALUE(O18)))),$T$4:$T$500))*1440),"") | Z18: =IFERROR(IF(Y18="","",IF(ROUND(Y18,0)<=15,"Cumple","No cumple")),"") | AB18: =IFERROR(IF(OR(O18="",R18=""),"",IF(IF(ISNUMBER(R18),MOD(R18,1),TIMEVALUE(R18))>=IF(ISNUMBER(O18),MOD(O18,1),TIMEVALUE(O18)),(IF(ISNUMBER(R18),MOD(R18,1),TIMEVALUE(R18))-IF(ISNUMBER(O18),MOD(O18,1),TIMEVALUE(O18)))*1440,(IF(ISNUMBER(R18),MOD(R18,1),TIMEVALUE(R18))+1-IF(ISNUMBER(O18),MOD(O18,1),TIMEVALUE(O18)))*1440)),"") | AC18: =IFERROR(IF(OR(R18="",S18=""),"",IF(IF(ISNUMBER(S18),MOD(S18,1),TIMEVALUE(S18))>=IF(ISNUMBER(R18),MOD(R18,1),TIMEVALUE(R18)),(IF(ISNUMBER(S18),MOD(S18,1),TIMEVALUE(S18))-IF(ISNUMBER(R18),MOD(R18,1),TIMEVALUE(R18)))*1440,(IF(ISNUMBER(S18),MOD(S18,1),TIMEVALUE(S18))+1-IF(ISNUMBER(R18),MOD(R18,1),TIMEVALUE(R18)))*1440)),"") | AE18: =IFERROR(IF(OR(AC18="",AD18=""),"",AC18-AD18),"") | AF18: =IFERROR(IF(AE18="","",IF(ROUND(AE18,0)>15,"Subestimacion",IF(ROUND(AE18,0)<-15,"Sobrestimacion","Asertivo"))),"") | AG18: No se presenta | AM18: I0001187222 | AP18: =IF(A18="","",A18-WEEKDAY(A18,2)+1) | AQ18: =IF(AO18="","",AO18+6) | AR18: =IF(AO18="","","Semana "&TEXT(AO18,"dd-mm-yyyy")&" al "&TEXT(AP18,"dd-mm-yyyy")) | AS18: =IF(A18="","",TEXT(A18,"mmmm yyyy")) | AT18: =IF(A18="","",TEXT(A18,"dddd")) | AU18: =IF(A18="","","CRR-"&TEXT(A18,"yyyymmdd")&"-"&M18&"-"&TEXT(ROW()-3,"0000")) | AV18: =IF(A18="","",IF(OR(B18="",C18="",E18="",F18="",M18="",N18=""),"Revisar campos obligatorios",IF(AND(P18="Atraso primera hora",Q18=""),"Falta justificación atraso primera hora",IF(AND(Z18="No cumple",AA18=""),"Falta justificación recambio >15 min",IF(AND(ISNUMBER(SEARCH("suspend",N18)),OR(AG18="",AH18="")),"Falta causa/motivo suspensión","OK"))))) | AW18: =IF(N18="","",IF(ISNUMBER(SEARCH("suspend",N18)),IF(AND(AG18="",AH18=""),"Sin causa/motivo registrado",IF(AG18="",AH18,IF(AH18="",AG18,AG18&": "&AH18))),""))
A19: 46167 | B19: LÚA AMARA | C19: HERMOSILLA | D19: 3a 10m 12d | E19: MANO DEDOS EN GATILLO, TRAT. QUIR., CUALQUIER NUMERO | F19: SERVICIO DE TRAUMATOLOGIA | H19: 2104093-4 | J19: =IF(H19<>"",IFERROR(VLOOKUP(IFERROR(LEFT(H19,FIND("-",H19)-1),H19),'Catalogo MINSAL'!A:E,5,FALSE),""),IF(I19<>"",IFERROR(VLOOKUP(IFERROR(LEFT(I19,FIND("-",I19)-1),I19),'Catalogo MINSAL'!A:E,5,FALSE),""),"")) | K19: Maximo Sepulveda Pizarro | L19: Dr. Isaías Sulantay Oyanedel | M19: Quirofano 13 | N19: Realizado | O19: 0.34236111 | P19: =IFERROR(IF(OR(O19="",A19="",M19=""),"",IF(SUMPRODUCT(($A$4:$A$500=A19)*($M$4:$M$500=M19)*($O$4:$O$500<>"")*(MOD($O$4:$O$500,1)<MOD(O19,1)))=0,IF(MOD(O19,1)<=TIME(8,15,0),"Ingreso adecuado primera hora","Atraso primera hora"),"No aplica")),"") | R19: 0.35833333 | S19: 0.375 | T19: 0.38333333 | U19: =IFERROR(VLOOKUP(M19,'Horario Pabellones'!$A$4:$D$17,2,FALSE),"") | V19: =IFERROR(VLOOKUP(M19,'Horario Pabellones'!$A$4:$D$17,3,FALSE),"") | W19: =IFERROR(VLOOKUP(M19,'Horario Pabellones'!$A$4:$D$17,4,FALSE),"") | X19: =IFERROR(IF(OR(A19="",M19="",W19=""),"",(((_xludf.AGGREGATE(14,6,MOD($S$4:$S$500,1)/(($A$4:$A$500=A19)*($M$4:$M$500=M19)*($R$4:$R$500<>"")*($S$4:$S$500<>"")),1)-_xludf.AGGREGATE(15,6,MOD($R$4:$R$500,1)/(($A$4:$A$500=A19)*($M$4:$M$500=M19)*($R$4:$R$500<>"")*($S$4:$S$500<>"")),1))*1440)/60)/(W19/60)),"") | Y19: =IFERROR(IF(OR(O19="",A19="",M19=""),"",(IF(ISNUMBER(O19),MOD(O19,1),TIMEVALUE(O19))-LOOKUP(2,1/(($A$4:$A$500=A19)*($M$4:$M$500=M19)*($T$4:$T$500<>"")*($T$4:$T$500<IF(ISNUMBER(O19),MOD(O19,1),TIMEVALUE(O19)))),$T$4:$T$500))*1440),"") | Z19: =IFERROR(IF(Y19="","",IF(ROUND(Y19,0)<=15,"Cumple","No cumple")),"") | AB19: =IFERROR(IF(OR(O19="",R19=""),"",IF(IF(ISNUMBER(R19),MOD(R19,1),TIMEVALUE(R19))>=IF(ISNUMBER(O19),MOD(O19,1),TIMEVALUE(O19)),(IF(ISNUMBER(R19),MOD(R19,1),TIMEVALUE(R19))-IF(ISNUMBER(O19),MOD(O19,1),TIMEVALUE(O19)))*1440,(IF(ISNUMBER(R19),MOD(R19,1),TIMEVALUE(R19))+1-IF(ISNUMBER(O19),MOD(O19,1),TIMEVALUE(O19)))*1440)),"") | AC19: =IFERROR(IF(OR(R19="",S19=""),"",IF(IF(ISNUMBER(S19),MOD(S19,1),TIMEVALUE(S19))>=IF(ISNUMBER(R19),MOD(R19,1),TIMEVALUE(R19)),(IF(ISNUMBER(S19),MOD(S19,1),TIMEVALUE(S19))-IF(ISNUMBER(R19),MOD(R19,1),TIMEVALUE(R19)))*1440,(IF(ISNUMBER(S19),MOD(S19,1),TIMEVALUE(S19))+1-IF(ISNUMBER(R19),MOD(R19,1),TIMEVALUE(R19)))*1440)),"") | AD19: 40 | AE19: =IFERROR(IF(OR(AC19="",AD19=""),"",AC19-AD19),"") | AF19: =IFERROR(IF(AE19="","",IF(ROUND(AE19,0)>15,"Subestimacion",IF(ROUND(AE19,0)<-15,"Sobrestimacion","Asertivo"))),"") | AG19: Sin Suspensión | AM19: I0001187195 | AP19: =IF(A19="","",A19-WEEKDAY(A19,2)+1) | AQ19: =IF(AO19="","",AO19+6) | AR19: =IF(AO19="","","Semana "&TEXT(AO19,"dd-mm-yyyy")&" al "&TEXT(AP19,"dd-mm-yyyy")) | AS19: =IF(A19="","",TEXT(A19,"mmmm yyyy")) | AT19: =IF(A19="","",TEXT(A19,"dddd")) | AU19: =IF(A19="","","CRR-"&TEXT(A19,"yyyymmdd")&"-"&M19&"-"&TEXT(ROW()-3,"0000")) | AV19: =IF(A19="","",IF(OR(B19="",C19="",E19="",F19="",M19="",N19=""),"Revisar campos obligatorios",IF(AND(P19="Atraso primera hora",Q19=""),"Falta justificación atraso primera hora",IF(AND(Z19="No cumple",AA19=""),"Falta justificación recambio >15 min",IF(AND(ISNUMBER(SEARCH("suspend",N19)),OR(AG19="",AH19="")),"Falta causa/motivo suspensión","OK"))))) | AW19: =IF(N19="","",IF(ISNUMBER(SEARCH("suspend",N19)),IF(AND(AG19="",AH19=""),"Sin causa/motivo registrado",IF(AG19="",AH19,IF(AH19="",AG19,AG19&": "&AH19))),""))
A20: 46167 | B20: DIEGO ALONSO | C20: MUGA | D20: 10a 8m 4d | E20: SINOVECTOMIAS QUIRURGICAS (PROC. AUT.) CODO O MUÑECA O METACARPOFALANGICAS, C/U | F20: SERVICIO DE TRAUMATOLOGIA | H20: 2104029-5 | J20: =IF(H20<>"",IFERROR(VLOOKUP(IFERROR(LEFT(H20,FIND("-",H20)-1),H20),'Catalogo MINSAL'!A:E,5,FALSE),""),IF(I20<>"",IFERROR(VLOOKUP(IFERROR(LEFT(I20,FIND("-",I20)-1),I20),'Catalogo MINSAL'!A:E,5,FALSE),""),"")) | K20: Maximo Sepulveda Pizarro | L20: Dr. Camilo Garcia | M20: Quirofano 13 | N20: Atendido | O20: 0.39930556 | P20: =IFERROR(IF(OR(O20="",A20="",M20=""),"",IF(SUMPRODUCT(($A$4:$A$500=A20)*($M$4:$M$500=M20)*($O$4:$O$500<>"")*(MOD($O$4:$O$500,1)<MOD(O20,1)))=0,IF(MOD(O20,1)<=TIME(8,15,0),"Ingreso adecuado primera hora","Atraso primera hora"),"No aplica")),"") | R20: 0.42152778 | S20: 0.45833333 | T20: 0.46666667 | U20: =IFERROR(VLOOKUP(M20,'Horario Pabellones'!$A$4:$D$17,2,FALSE),"") | V20: =IFERROR(VLOOKUP(M20,'Horario Pabellones'!$A$4:$D$17,3,FALSE),"") | W20: =IFERROR(VLOOKUP(M20,'Horario Pabellones'!$A$4:$D$17,4,FALSE),"") | X20: =IFERROR(IF(OR(A20="",M20="",W20=""),"",(((_xludf.AGGREGATE(14,6,MOD($S$4:$S$500,1)/(($A$4:$A$500=A20)*($M$4:$M$500=M20)*($R$4:$R$500<>"")*($S$4:$S$500<>"")),1)-_xludf.AGGREGATE(15,6,MOD($R$4:$R$500,1)/(($A$4:$A$500=A20)*($M$4:$M$500=M20)*($R$4:$R$500<>"")*($S$4:$S$500<>"")),1))*1440)/60)/(W20/60)),"") | Y20: =IFERROR(IF(OR(O20="",A20="",M20=""),"",(IF(ISNUMBER(O20),MOD(O20,1),TIMEVALUE(O20))-LOOKUP(2,1/(($A$4:$A$500=A20)*($M$4:$M$500=M20)*($T$4:$T$500<>"")*($T$4:$T$500<IF(ISNUMBER(O20),MOD(O20,1),TIMEVALUE(O20)))),$T$4:$T$500))*1440),"") | Z20: =IFERROR(IF(Y20="","",IF(ROUND(Y20,0)<=15,"Cumple","No cumple")),"") | AB20: =IFERROR(IF(OR(O20="",R20=""),"",IF(IF(ISNUMBER(R20),MOD(R20,1),TIMEVALUE(R20))>=IF(ISNUMBER(O20),MOD(O20,1),TIMEVALUE(O20)),(IF(ISNUMBER(R20),MOD(R20,1),TIMEVALUE(R20))-IF(ISNUMBER(O20),MOD(O20,1),TIMEVALUE(O20)))*1440,(IF(ISNUMBER(R20),MOD(R20,1),TIMEVALUE(R20))+1-IF(ISNUMBER(O20),MOD(O20,1),TIMEVALUE(O20)))*1440)),"") | AC20: =IFERROR(IF(OR(R20="",S20=""),"",IF(IF(ISNUMBER(S20),MOD(S20,1),TIMEVALUE(S20))>=IF(ISNUMBER(R20),MOD(R20,1),TIMEVALUE(R20)),(IF(ISNUMBER(S20),MOD(S20,1),TIMEVALUE(S20))-IF(ISNUMBER(R20),MOD(R20,1),TIMEVALUE(R20)))*1440,(IF(ISNUMBER(S20),MOD(S20,1),TIMEVALUE(S20))+1-IF(ISNUMBER(R20),MOD(R20,1),TIMEVALUE(R20)))*1440)),"") | AD20: 45 | AE20: =IFERROR(IF(OR(AC20="",AD20=""),"",AC20-AD20),"") | AF20: =IFERROR(IF(AE20="","",IF(ROUND(AE20,0)>15,"Subestimacion",IF(ROUND(AE20,0)<-15,"Sobrestimacion","Asertivo"))),"") | AG20: Sin Suspensión | AM20: I0001187199 | AP20: =IF(A20="","",A20-WEEKDAY(A20,2)+1) | AQ20: =IF(AO20="","",AO20+6) | AR20: =IF(AO20="","","Semana "&TEXT(AO20,"dd-mm-yyyy")&" al "&TEXT(AP20,"dd-mm-yyyy")) | AS20: =IF(A20="","",TEXT(A20,"mmmm yyyy")) | AT20: =IF(A20="","",TEXT(A20,"dddd")) | AU20: =IF(A20="","","CRR-"&TEXT(A20,"yyyymmdd")&"-"&M20&"-"&TEXT(ROW()-3,"0000")) | AV20: =IF(A20="","",IF(OR(B20="",C20="",E20="",F20="",M20="",N20=""),"Revisar campos obligatorios",IF(AND(P20="Atraso primera hora",Q20=""),"Falta justificación atraso primera hora",IF(AND(Z20="No cumple",AA20=""),"Falta justificación recambio >15 min",IF(AND(ISNUMBER(SEARCH("suspend",N20)),OR(AG20="",AH20="")),"Falta causa/motivo suspensión","OK"))))) | AW20: =IF(N20="","",IF(ISNUMBER(SEARCH("suspend",N20)),IF(AND(AG20="",AH20=""),"Sin causa/motivo registrado",IF(AG20="",AH20,IF(AH20="",AG20,AG20&": "&AH20))),""))
A21: 46167 | B21: KARL-HERTZ STURRIDGE | C21: DESVALLONS | D21: 11a 4m 1d | E21: RETIRO DE TORNILLOS, CLAVOS, AGUJAS DE OSTEOSINTESIS O SIMILARES | F21: SERVICIO DE TRAUMATOLOGIA | H21: 2106003-5 | J21: =IF(H21<>"",IFERROR(VLOOKUP(IFERROR(LEFT(H21,FIND("-",H21)-1),H21),'Catalogo MINSAL'!A:E,5,FALSE),""),IF(I21<>"",IFERROR(VLOOKUP(IFERROR(LEFT(I21,FIND("-",I21)-1),I21),'Catalogo MINSAL'!A:E,5,FALSE),""),"")) | K21: Maximo Sepulveda Pizarro | L21: Dr. Isaías Sulantay Oyanedel | M21: Quirofano 13 | N21: Atendido | O21: 0.47777778 | P21: =IFERROR(IF(OR(O21="",A21="",M21=""),"",IF(SUMPRODUCT(($A$4:$A$500=A21)*($M$4:$M$500=M21)*($O$4:$O$500<>"")*(MOD($O$4:$O$500,1)<MOD(O21,1)))=0,IF(MOD(O21,1)<=TIME(8,15,0),"Ingreso adecuado primera hora","Atraso primera hora"),"No aplica")),"") | R21: 0.50763889 | S21: 0.55208333 | T21: 0.56597222 | U21: =IFERROR(VLOOKUP(M21,'Horario Pabellones'!$A$4:$D$17,2,FALSE),"") | V21: =IFERROR(VLOOKUP(M21,'Horario Pabellones'!$A$4:$D$17,3,FALSE),"") | W21: =IFERROR(VLOOKUP(M21,'Horario Pabellones'!$A$4:$D$17,4,FALSE),"") | X21: =IFERROR(IF(OR(A21="",M21="",W21=""),"",(((_xludf.AGGREGATE(14,6,MOD($S$4:$S$500,1)/(($A$4:$A$500=A21)*($M$4:$M$500=M21)*($R$4:$R$500<>"")*($S$4:$S$500<>"")),1)-_xludf.AGGREGATE(15,6,MOD($R$4:$R$500,1)/(($A$4:$A$500=A21)*($M$4:$M$500=M21)*($R$4:$R$500<>"")*($S$4:$S$500<>"")),1))*1440)/60)/(W21/60)),"") | Y21: =IFERROR(IF(OR(O21="",A21="",M21=""),"",(IF(ISNUMBER(O21),MOD(O21,1),TIMEVALUE(O21))-LOOKUP(2,1/(($A$4:$A$500=A21)*($M$4:$M$500=M21)*($T$4:$T$500<>"")*($T$4:$T$500<IF(ISNUMBER(O21),MOD(O21,1),TIMEVALUE(O21)))),$T$4:$T$500))*1440),"") | Z21: =IFERROR(IF(Y21="","",IF(ROUND(Y21,0)<=15,"Cumple","No cumple")),"") | AB21: =IFERROR(IF(OR(O21="",R21=""),"",IF(IF(ISNUMBER(R21),MOD(R21,1),TIMEVALUE(R21))>=IF(ISNUMBER(O21),MOD(O21,1),TIMEVALUE(O21)),(IF(ISNUMBER(R21),MOD(R21,1),TIMEVALUE(R21))-IF(ISNUMBER(O21),MOD(O21,1),TIMEVALUE(O21)))*1440,(IF(ISNUMBER(R21),MOD(R21,1),TIMEVALUE(R21))+1-IF(ISNUMBER(O21),MOD(O21,1),TIMEVALUE(O21)))*1440)),"") | AC21: =IFERROR(IF(OR(R21="",S21=""),"",IF(IF(ISNUMBER(S21),MOD(S21,1),TIMEVALUE(S21))>=IF(ISNUMBER(R21),MOD(R21,1),TIMEVALUE(R21)),(IF(ISNUMBER(S21),MOD(S21,1),TIMEVALUE(S21))-IF(ISNUMBER(R21),MOD(R21,1),TIMEVALUE(R21)))*1440,(IF(ISNUMBER(S21),MOD(S21,1),TIMEVALUE(S21))+1-IF(ISNUMBER(R21),MOD(R21,1),TIMEVALUE(R21)))*1440)),"") | AD21: 60 | AE21: =IFERROR(IF(OR(AC21="",AD21=""),"",AC21-AD21),"") | AF21: =IFERROR(IF(AE21="","",IF(ROUND(AE21,0)>15,"Subestimacion",IF(ROUND(AE21,0)<-15,"Sobrestimacion","Asertivo"))),"") | AG21: Sin Suspensión | AM21: I0001187201 | AP21: =IF(A21="","",A21-WEEKDAY(A21,2)+1) | AQ21: =IF(AO21="","",AO21+6) | AR21: =IF(AO21="","","Semana "&TEXT(AO21,"dd-mm-yyyy")&" al "&TEXT(AP21,"dd-mm-yyyy")) | AS21: =IF(A21="","",TEXT(A21,"mmmm yyyy")) | AT21: =IF(A21="","",TEXT(A21,"dddd")) | AU21: =IF(A21="","","CRR-"&TEXT(A21,"yyyymmdd")&"-"&M21&"-"&TEXT(ROW()-3,"0000")) | AV21: =IF(A21="","",IF(OR(B21="",C21="",E21="",F21="",M21="",N21=""),"Revisar campos obligatorios",IF(AND(P21="Atraso primera hora",Q21=""),"Falta justificación atraso primera hora",IF(AND(Z21="No cumple",AA21=""),"Falta justificación recambio >15 min",IF(AND(ISNUMBER(SEARCH("suspend",N21)),OR(AG21="",AH21="")),"Falta causa/motivo suspensión","OK"))))) | AW21: =IF(N21="","",IF(ISNUMBER(SEARCH("suspend",N21)),IF(AND(AG21="",AH21=""),"Sin causa/motivo registrado",IF(AG21="",AH21,IF(AH21="",AG21,AG21&": "&AH21))),""))
